Workbook

Sheet ร้านใกล้แหล่งท่องเที่ยว
A1: ลำดับ | B1: แหล่งท่องเที่ยว | C1: ประเภท | D1: ชื่อร้าน | E1: ละติจูด | F1: ลองจิจูด | G1: ระยะห่างจากแหล่งท่องเที่ยว (กม.) | H1: ที่อยู่ | I1: วัน-เวลาเปิดให้บริการ | J1: เบอร์โทร | K1: ลิงก์ Google Maps | L1: สถานะ (ตรวจสอบ 3 ต.ค. 2569)
A2: 1 | B2: SkyWalk King Power Mahanakhon (คิงเพาเวอร์ มหานคร) | C2: ร้านอาหาร | D2: Mahanakhon Eatery | E2: 13.723905 | F2: 100.52865 | G2: 0.02 | H2: 96 ถ.นราธิวาสราชนครินทร์ สีลม บางรัก | I2: ทุกวัน 08:00-22:00 | J2: +66 2 677 8721 | K2: =HYPERLINK("https://www.google.com/maps/search/?api=1&query=Mahanakhon%20Eatery&query_place_id=ChIJpYfHXaef4jARpiefh3BHf1k","เปิดแผนที่") -> เปิดแผนที่ | L2: เปิดให้บริการ (มีเวลาทำการใน Google Maps)
A3: 2 | B3: SkyWalk King Power Mahanakhon (คิงเพาเวอร์ มหานคร) | C3: ร้านอาหาร | D3: Babyccino Mahanakhon | E3: 13.72386 | F3: 100.52868 | G3: 0.03 | H3: Mahanakhon Cube 96 ถ.นราธิวาสฯ สีลม บางรัก | I3: ทุกวัน 10:00-22:00 | J3: +66 92 446 9222 | K3: =HYPERLINK("https://www.google.com/maps/search/?api=1&query=Babyccino%20Mahanakhon&query_place_id=ChIJL_Skva2Z4jARptt0z0enAIM","เปิดแผนที่") -> เปิดแผนที่ | L3: เปิดให้บริการ (มีเวลาทำการใน Google Maps)
A4: 3 | B4: SkyWalk King Power Mahanakhon (คิงเพาเวอร์ มหานคร) | C4: ร้านอาหาร | D4: The Standard Grill | E4: 13.72353 | F4: 100.5283 | G4: 0.06 | H4: ชั้น 5 The Standard Bangkok Mahanakhon 114 ถ.นราธิวาสฯ | I4: จ-ศ 17:30-22:30 / ส-อา 12:00-15:00, 17:30-22:30 | J4: +66 2 085 8888 | K4: =HYPERLINK("https://www.google.com/maps/search/?api=1&query=The%20Standard%20Grill&query_place_id=ChIJtzsv7T2Z4jAR2fSNVxk9_Jc","เปิดแผนที่") -> เปิดแผนที่ | L4: เปิดให้บริการ (มีเวลาทำการใน Google Maps)
A5: 4 | B5: SkyWalk King Power Mahanakhon (คิงเพาเวอร์ มหานคร) | C5: ร้านเครื่องดื่ม | D5: Sugar Bliss Coffee & Brunch (Ashton Silom) | E5: 13.726351 | F5: 100.52681 | G5: 0.32 | H5: Ashton Silom ถ.สีลม สุริยวงศ์ บางรัก | I5: ทุกวัน 08:00-18:00 | J5: +66 93 452 2989 | K5: =HYPERLINK("https://www.google.com/maps/search/?api=1&query=Sugar%20Bliss%20Coffee%20%26%20Brunch%20%28Ashton%20Silom%29&query_place_id=ChIJ_9mRbwqZ4jAR5qjatMOK910","เปิดแผนที่") -> เปิดแผนที่ | L5: เปิดให้บริการ (มีเวลาทำการใน Google Maps)
A6: 5 | B6: SkyWalk King Power Mahanakhon (คิงเพาเวอร์ มหานคร) | C6: ร้านเครื่องดื่ม | D6: Still Bean — Silom | E6: 13.727425 | F6: 100.53329 | G6: 0.64 | H6: 2, 3 ถ.คอนแวนต์ สีลม บางรัก | I6: ทุกวัน 07:30-20:00 | J6: +66 2 000 0101 | K6: =HYPERLINK("https://www.google.com/maps/search/?api=1&query=Still%20Bean%20%E2%80%94%20Silom&query_place_id=ChIJpY1mWCaf4jARIHPxN0HALGc","เปิดแผนที่") -> เปิดแผนที่ | L6: เปิดให้บริการ (มีเวลาทำการใน Google Maps)
A7: 6 | B7: SkyWalk King Power Mahanakhon (คิงเพาเวอร์ มหานคร) | C7: ร้านเครื่องดื่ม | D7: GATTA Cafe (Park Silom) - Specialty Coffee | E7: 13.727861 | F7: 100.53353 | G7: 0.69 | H7: ชั้น L Park Silom ถ.สีลม บางรัก | I7: จ-ศ 07:00-17:30 / ส-อา 08:00-16:30 | J7: +66 96 079 8822 | K7: =HYPERLINK("https://www.google.com/maps/search/?api=1&query=GATTA%20Cafe%20%28Park%20Silom%29%20-%20Specialty%20Coffee&query_place_id=ChIJ54yK4R2f4jARqeeHInvT16Y","เปิดแผนที่") -> เปิดแผนที่ | L7: เปิดให้บริการ (มีเวลาทำการใน Google Maps)
A8: 7 | B8: SkyWalk King Power Mahanakhon (คิงเพาเวอร์ มหานคร) | C8: ร้านของหวาน | D8: Brioche from Heaven | E8: 13.724035 | F8: 100.5296 | G8: 0.12 | H8: 156 ถ.นราธิวาสราชนครินทร์ สีลม บางรัก | I8: ทุกวัน 08:30-18:30 | J8: +66 64 847 0049 | K8: =HYPERLINK("https://www.google.com/maps/search/?api=1&query=Brioche%20from%20Heaven&query_place_id=ChIJsbfRmjGZ4jARcKFHjhSe1ls","เปิดแผนที่") -> เปิดแผนที่ | L8: เปิดให้บริการ (มีเวลาทำการใน Google Maps)
A9: 8 | B9: SkyWalk King Power Mahanakhon (คิงเพาเวอร์ มหานคร) | C9: ร้านของหวาน | D9: After You Dessert Café (Silom Complex) | E9: 13.728473 | F9: 100.53504 | G9: 0.86 | H9: Silom Complex ชั้น 2 191 ถ.สีลม บางรัก | I9: ทุกวัน 10:30-21:00 | J9: +66 2 231 3255 | K9: =HYPERLINK("https://www.google.com/maps/search/?api=1&query=After%20You%20Dessert%20Caf%C3%A9%20%28Silom%20Complex%29&query_place_id=ChIJa2em1dGY4jARkD433irtHU8","เปิดแผนที่") -> เปิดแผนที่ | L9: เปิดให้บริการ (มีเวลาทำการใน Google Maps)
A10: 9 | B10: SkyWalk King Power Mahanakhon (คิงเพาเวอร์ มหานคร) | C10: ร้านของหวาน | D10: Kyo Roll En (Silom Complex) | E10: 13.728085 | F10: 100.53494 | G10: 0.83 | H10: Silom Complex ชั้น B 191 ถ.สีลม บางรัก | I10: ทุกวัน 10:30-22:00 | J10: +66 65 717 9010 | K10: =HYPERLINK("https://www.google.com/maps/search/?api=1&query=Kyo%20Roll%20En%20%28Silom%20Complex%29&query_place_id=ChIJr9hEAyyf4jARq1DOwvgEalo","เปิดแผนที่") -> เปิดแผนที่ | L10: เปิดให้บริการ (มีเวลาทำการใน Google Maps)
A11: 10 | B11: วัดพระศรีรัตนศาสดาราม (วัดพระแก้ว) | C11: ร้านอาหาร | D11: Thong Heng Lee Restaurant | E11: 13.752679 | F11: 100.48939 | G11: 0.38 | H11: 192-194 ถ.มหาราช พระบรมมหาราชวัง พระนคร | I11: อ-อา 08:30-16:30 (ปิดวันจันทร์) | J11: +66 81 649 4890 | K11: =HYPERLINK("https://www.google.com/maps/search/?api=1&query=Thong%20Heng%20Lee%20Restaurant&query_place_id=ChIJqda0RQmZ4jAR861kobU9SaE","เปิดแผนที่") -> เปิดแผนที่ | L11: เปิดให้บริการ (มีเวลาทำการใน Google Maps)
A12: 11 | B12: วัดพระศรีรัตนศาสดาราม (วัดพระแก้ว) | C12: ร้านอาหาร | D12: The Gate Grand Palace | E12: 13.752174 | F12: 100.48915 | G12: 0.39 | H12: 77 ถ.หน้าพระลาน ท่าช้าง พระนคร | I12: ทุกวัน 09:00-18:00 | J12: +66 82 752 4993 | K12: =HYPERLINK("https://www.google.com/maps/search/?api=1&query=The%20Gate%20Grand%20Palace&query_place_id=ChIJXSG1gOGZ4jARQWWzQjSY8Hw","เปิดแผนที่") -> เปิดแผนที่ | L12: เปิดให้บริการ (มีเวลาทำการใน Google Maps)
A13: 12 | B13: วัดพระศรีรัตนศาสดาราม (วัดพระแก้ว) | C13: ร้านอาหาร | D13: Thai Royal Kitchen ครัวหน้าวัง | E13: 13.749529 | F13: 100.49827 | G13: 0.64 | H13: 12 ถ.ราชบพิธ วัดราชบพิธ พระนคร | I13: ทุกวัน 05:30-14:00 (แนะนำสั่งล่วงหน้า) | J13: +66 63 965 5656 | K13: =HYPERLINK("https://www.google.com/maps/search/?api=1&query=Thai%20Royal%20Kitchen%20%E0%B8%84%E0%B8%A3%E0%B8%B1%E0%B8%A7%E0%B8%AB%E0%B8%99%E0%B9%89%E0%B8%B2%E0%B8%A7%E0%B8%B1%E0%B8%87&query_place_id=ChIJ3RQGqDKZ4jARor7IX-x0y0s","เปิดแผนที่") -> เปิดแผนที่ | L13: เปิดให้บริการ (มีเวลาทำการใน Google Maps)
A14: 13 | B14: วัดพระศรีรัตนศาสดาราม (วัดพระแก้ว) | C14: ร้านเครื่องดื่ม | D14: Tawang Thai Tea, Legendary of LIGOR @Wat Phra Kaew | E14: 13.75252 | F14: 100.49085 | G14: 0.23 | H14: 9 ถ.หน้าพระลาน พระบรมมหาราชวัง พระนคร | I14: ทุกวัน 09:00-17:00 | J14: +66 88 980 9398 | K14: =HYPERLINK("https://www.google.com/maps/search/?api=1&query=Tawang%20Thai%20Tea%2C%20Legendary%20of%20LIGOR%20%40Wat%20Phra%20Kaew&query_place_id=ChIJX1I3HwCZ4jARxCmOcCGCapw","เปิดแผนที่") -> เปิดแผนที่ | L14: เปิดให้บริการ (มีเวลาทำการใน Google Maps)
A15: 14 | B15: วัดพระศรีรัตนศาสดาราม (วัดพระแก้ว) | C15: ร้านเครื่องดื่ม | D15: Cloud Phranakhon | E15: 13.75562 | F15: 100.49205 | G15: 0.46 | H15: ซ.หน้าพระธาตุ พระบรมมหาราชวัง พระนคร | I15: ทุกวัน 07:00-21:00 | J15: +66 80 296 5549 | K15: =HYPERLINK("https://www.google.com/maps/search/?api=1&query=Cloud%20Phranakhon&query_place_id=ChIJ0VnuaBeZ4jARYxkgVt-fU-o","เปิดแผนที่") -> เปิดแผนที่ | L15: เปิดให้บริการ (มีเวลาทำการใน Google Maps)
A16: 15 | B16: วัดพระศรีรัตนศาสดาราม (วัดพระแก้ว) | C16: ร้านเครื่องดื่ม | D16: ช่างคั่ว สาขาท่าพระจันทร์ | E16: 13.75591 | F16: 100.49041 | G16: 0.55 | H16: 5-7 ซ.ท่าพระจันทร์ พระบรมมหาราชวัง พระนคร | I16: ทุกวัน 08:00-16:00 | J16: +66 96 395 9446 | K16: =HYPERLINK(_xlfn._LONGTEXT("https://www.google.com/maps/search/?api=1&query=%E0%B8%8A%E0%B9%88%E0%B8%B2%E0%B8%87%E0%B8%84%E0%B8%B1%E0%B9%88%E0%B8%A7%20%E0%B8%AA%E0%B8%B2%E0%B8%82%E0%B8%B2%E0%B8%97%E0%B9%88%E0%B8%B2%E0%B8%9E%E0%B8%A3%E0%B8%B0%E0%B8%88%E0%B8%B1%E0%B8%99%E0%B8%97%E0%B8","%A3%E0%B9%8C&query_place_id=ChIJnx1_2XKZ4jARlAWQwKo5-_Y"),"เปิดแผนที่") -> #VALUE! | L16: เปิดให้บริการ (มีเวลาทำการใน Google Maps)
A17: 16 | B17: วัดพระศรีรัตนศาสดาราม (วัดพระแก้ว) | C17: ร้านของหวาน | D17: Nuttaporn Ice Cream (ไอศกรีมมะพร้าวนัฐพร) | E17: 13.75167 | F17: 100.4975 | G17: 0.52 | H17: 94 ถ.แพร่งภูธร ศาลเจ้าพ่อเสือ พระนคร | I17: จ-ส 09:00-17:00 (ปิดวันอาทิตย์) | J17: +66 89 826 5752 | K17: =HYPERLINK(_xlfn._LONGTEXT("https://www.google.com/maps/search/?api=1&query=Nuttaporn%20Ice%20Cream%20%28%E0%B9%84%E0%B8%AD%E0%B8%A8%E0%B8%81%E0%B8%A3%E0%B8%B5%E0%B8%A1%E0%B8%A1%E0%B8%B0%E0%B8%9E%E0%B8%A3%E0%B9%89%E0%B8%B2%E0%B8%A7%E0%B8%99%E0%B8%B1%E0%B8%90%E0%B8%9E%E0%B8%A3%29&que","ry_place_id=ChIJ5VJGvhGZ4jARSBZl5Kc7a2k"),"เปิดแผนที่") -> #VALUE! | L17: เปิดให้บริการ (มีเวลาทำการใน Google Maps)
A18: 17 | B18: วัดพระศรีรัตนศาสดาราม (วัดพระแก้ว) | C18: ร้านของหวาน | D18: ร้านลุงแดง (ขนมไทยโบราณ แพร่งนรา) | E18: 13.752426 | F18: 100.498 | G18: 0.58 | H18: 112 ถ.แพร่งนรา ศาลเจ้าพ่อเสือ พระนคร | I18: จ-ศ 09:00-15:00 (ปิดเสาร์-อาทิตย์) | J18: +66 2 622 0404 | K18: =HYPERLINK(_xlfn._LONGTEXT("https://www.google.com/maps/search/?api=1&query=%E0%B8%A3%E0%B9%89%E0%B8%B2%E0%B8%99%E0%B8%A5%E0%B8%B8%E0%B8%87%E0%B9%81%E0%B8%94%E0%B8%87%20%28%E0%B8%82%E0%B8%99%E0%B8%A1%E0%B9%84%E0%B8%97%E0%B8%A2%E0%B9%82%E0%B8%9A%E0%B8%A3%E0%B8%B2%E0%B8%93%20%E0%B9%81","%E0%B8%9E%E0%B8%A3%E0%B9%88%E0%B8%87%E0%B8%99%E0%B8%A3%E0%B8%B2%29&query_place_id=ChIJa0NEkBGZ4jARK8fGc1AlX4k"),"เปิดแผนที่") -> #VALUE! | L18: เปิดให้บริการ (มีเวลาทำการใน Google Maps)
A19: 18 | B19: วัดพระศรีรัตนศาสดาราม (วัดพระแก้ว) | C19: ร้านของหวาน | D19: PAULETTE BKK | E19: 13.749523 | F19: 100.49804 | G19: 0.62 | H19: 65 ถ.เฟื่องนคร วัดราชบพิธ พระนคร | I19: ทุกวัน 07:30-18:30 | J19: +66 63 674 6561 | K19: =HYPERLINK("https://www.google.com/maps/search/?api=1&query=PAULETTE%20BKK&query_place_id=ChIJHdQm8CKZ4jARSeplrVUwAtg","เปิดแผนที่") -> เปิดแผนที่ | L19: เปิดให้บริการ (มีเวลาทำการใน Google Maps)
A20: 19 | B20: วัดพระเชตุพนวิมลมังคลาราม (วัดโพธิ์) | C20: ร้านอาหาร | D20: Baan ThaTien | E20: 13.744685 | F20: 100.49225 | G20: 0.2 | H20: 392/2 ถ.มหาราช พระบรมมหาราชวัง พระนคร | I20: ทุกวัน 08:00-19:00 | J20: +66 95 151 5545 | K20: =HYPERLINK("https://www.google.com/maps/search/?api=1&query=Baan%20ThaTien&query_place_id=ChIJAYJsTQSZ4jARi7QrBrmpxY4","เปิดแผนที่") -> เปิดแผนที่ | L20: เปิดให้บริการ (มีเวลาทำการใน Google Maps)
A21: 20 | B21: วัดพระเชตุพนวิมลมังคลาราม (วัดโพธิ์) | C21: ร้านอาหาร | D21: Home Cafe Tha Tien | E21: 13.745695 | F21: 100.49125 | G21: 0.18 | H21: 10-14 ซ.ท่าเตียน พระบรมมหาราชวัง พระนคร | I21: จ-ส 10:30-19:00 (ปิดวันอาทิตย์) | J21: +66 2 622 1936 | K21: =HYPERLINK("https://www.google.com/maps/search/?api=1&query=Home%20Cafe%20Tha%20Tien&query_place_id=ChIJ6aLoxQWZ4jARd7FjOaPiQ08","เปิดแผนที่") -> เปิดแผนที่ | L21: เปิดให้บริการ (มีเวลาทำการใน Google Maps)
A22: 21 | B22: วัดพระเชตุพนวิมลมังคลาราม (วัดโพธิ์) | C22: ร้านอาหาร | D22: RONGROS | E22: 13.744255 | F22: 100.49171 | G22: 0.27 | H22: 392/16 ถ.มหาราช พระบรมมหาราชวัง พระนคร | I22: ทุกวัน 11:00-15:00, 17:00-22:00 | J22: +66 96 946 1785 | K22: =HYPERLINK("https://www.google.com/maps/search/?api=1&query=RONGROS&query_place_id=ChIJjYPUa8GZ4jARi9fgigQOiR8","เปิดแผนที่") -> เปิดแผนที่ | L22: เปิดให้บริการ (มีเวลาทำการใน Google Maps)
A23: 22 | B23: วัดพระเชตุพนวิมลมังคลาราม (วัดโพธิ์) | C23: ร้านเครื่องดื่ม | D23: Orin Coffee roaster & Specialty tea | E23: 13.745606 | F23: 100.49115 | G23: 0.2 | H23: 20 ซ.ท่าเตียน พระบรมมหาราชวัง พระนคร | I23: ทุกวัน 08:00-18:00 (ปิดวันพุธ) | J23: +66 88 666 2027 | K23: =HYPERLINK("https://www.google.com/maps/search/?api=1&query=Orin%20Coffee%20roaster%20%26%20Specialty%20tea&query_place_id=ChIJ3cc_YhmZ4jARPfL1wgx3Ywk","เปิดแผนที่") -> เปิดแผนที่ | L23: เปิดให้บริการ (มีเวลาทำการใน Google Maps)
A24: 23 | B24: วัดพระเชตุพนวิมลมังคลาราม (วัดโพธิ์) | C24: ร้านเครื่องดื่ม | D24: SLOWBAR : Slow coffee & Juice bar | E24: 13.745341 | F24: 100.49164 | G24: 0.17 | H24: 85/2 พระบรมมหาราชวัง พระนคร | I24: ทุกวัน 10:00-19:00 (ปิดวันอังคาร) | J24: +66 94 952 6463 | K24: =HYPERLINK("https://www.google.com/maps/search/?api=1&query=SLOWBAR%20%3A%20Slow%20coffee%20%26%20Juice%20bar&query_place_id=ChIJI7VVefWZ4jARWW57XZMlPO4","เปิดแผนที่") -> เปิดแผนที่ | L24: เปิดให้บริการ (มีเวลาทำการใน Google Maps)
A25: 24 | B25: วัดพระเชตุพนวิมลมังคลาราม (วัดโพธิ์) | C25: ร้านเครื่องดื่ม | D25: ตั้งเตียนน์ - Tang De Tien Cafe' & Curated twist | E25: 13.746025 | F25: 100.4912 | G25: 0.17 | H25: 312-314 ถ.มหาราช พระบรมมหาราชวัง พระนคร | I25: ทุกวัน 09:30-20:30 | J25: +66 61 415 1555 | K25: =HYPERLINK("https://www.google.com/maps/search/?api=1&query=%E0%B8%95%E0%B8%B1%E0%B9%89%E0%B8%87%E0%B9%80%E0%B8%95%E0%B8%B5%E0%B8%A2%E0%B8%99%E0%B8%99%E0%B9%8C%20-%20Tang%20De%20Tien%20Cafe%27%20%26%20Curated%20twist&query_place_id=ChIJpRm_RwCZ4jARHuxdKSbqYX0","เปิดแผนที่") -> เปิดแผนที่ | L25: เปิดให้บริการ (มีเวลาทำการใน Google Maps)
A26: 25 | B26: วัดพระเชตุพนวิมลมังคลาราม (วัดโพธิ์) | C26: ร้านของหวาน | D26: Heychom Thai Dessert Bar | E26: 13.74592 | F26: 100.49127 | G26: 0.17 | H26: 320 ถ.มหาราช พระบรมมหาราชวัง พระนคร | I26: ทุกวัน 11:00-18:00 | J26: +66 99 239 9246 | K26: =HYPERLINK("https://www.google.com/maps/search/?api=1&query=Heychom%20Thai%20Dessert%20Bar&query_place_id=ChIJf676IJeZ4jARHVCHVT4OJko","เปิดแผนที่") -> เปิดแผนที่ | L26: เปิดให้บริการ (มีเวลาทำการใน Google Maps)
A27: 26 | B27: วัดพระเชตุพนวิมลมังคลาราม (วัดโพธิ์) | C27: ร้านของหวาน | D27: After Sunrise | E27: 13.745007 | F27: 100.49194 | G27: 0.18 | H27: 370 ชั้น 2 Chetuphon Gate ซ.ประตูนกยูง พระนคร | I27: ทุกวัน 12:00-20:00 | J27: - | K27: =HYPERLINK("https://www.google.com/maps/search/?api=1&query=After%20Sunrise&query_place_id=ChIJ2ewOZh6Z4jARqNuLp2xFDW8","เปิดแผนที่") -> เปิดแผนที่ | L27: เปิดให้บริการ (มีเวลาทำการใน Google Maps)
A28: 27 | B28: วัดพระเชตุพนวิมลมังคลาราม (วัดโพธิ์) | C28: ร้านของหวาน | D28: A Pink Rabbit + Bob | E28: 13.744936 | F28: 100.49202 | G28: 0.18 | H28: 378 ถ.มหาราช พระบรมมหาราชวัง พระนคร | I28: ทุกวัน 09:00-20:00 | J28: +66 62 639 8880 | K28: =HYPERLINK("https://www.google.com/maps/search/?api=1&query=A%20Pink%20Rabbit%20%2B%20Bob&query_place_id=ChIJv9Qyc9uZ4jAR7LyLQfsLySI","เปิดแผนที่") -> เปิดแผนที่ | L28: เปิดให้บริการ (มีเวลาทำการใน Google Maps)
A29: 28 | B29: วัดอรุณราชวรารามราชวรมหาวิหาร | C29: ร้านอาหาร | D29: Chom Arun | E29: 13.744048 | F29: 100.49177 | G29: 0.36 | H29: 392/53 ถ.มหาราช พระบรมมหาราชวัง พระนคร | I29: ทุกวัน 10:30-21:30 | J29: +66 95 446 4199 | K29: =HYPERLINK("https://www.google.com/maps/search/?api=1&query=Chom%20Arun&query_place_id=ChIJg86wsZ-Z4jARYyyrIYV1rpw","เปิดแผนที่") -> เปิดแผนที่ | L29: เปิดให้บริการ (มีเวลาทำการใน Google Maps)
A30: 29 | B30: วัดอรุณราชวรารามราชวรมหาวิหาร | C30: ร้านอาหาร | D30: Supanniga Eating Room Tha Tien | E30: 13.744135 | F30: 100.49173 | G30: 0.36 | H30: 392/25-26 ซ.เพ็ญพัฒน์ 2 พระบรมมหาราชวัง พระนคร | I30: จ-ศ 11:00-22:00 / ส-อา 10:00-22:00 | J30: +66 92 253 9251 | K30: =HYPERLINK("https://www.google.com/maps/search/?api=1&query=Supanniga%20Eating%20Room%20Tha%20Tien&query_place_id=ChIJjZS9RwSZ4jARNZMgiT03fJ4","เปิดแผนที่") -> เปิดแผนที่ | L30: เปิดให้บริการ (มีเวลาทำการใน Google Maps)
A31: 30 | B31: วัดอรุณราชวรารามราชวรมหาวิหาร | C31: ร้านอาหาร | D31: Eat Sight Story Deck | E31: 13.745267 | F31: 100.49095 | G31: 0.31 | H31: 47-79 ซ.ท่าเตียน พระบรมมหาราชวัง พระนคร | I31: ทุกวัน 11:00-22:00 | J31: +66 83 988 8735 | K31: =HYPERLINK("https://www.google.com/maps/search/?api=1&query=Eat%20Sight%20Story%20Deck&query_place_id=ChIJ961s0QWZ4jARvvtf8tT2ZzQ","เปิดแผนที่") -> เปิดแผนที่ | L31: เปิดให้บริการ (มีเวลาทำการใน Google Maps)
A32: 31 | B32: วัดอรุณราชวรารามราชวรมหาวิหาร | C32: ร้านเครื่องดื่ม | D32: ViVi The Coffee Place | E32: 13.743691 | F32: 100.49211 | G32: 0.4 | H32: 394/29 ซ.ปานสุข พระบรมมหาราชวัง พระนคร | I32: ทุกวัน 10:00-20:00 | J32: +66 2 226 4672 | K32: =HYPERLINK("https://www.google.com/maps/search/?api=1&query=ViVi%20The%20Coffee%20Place&query_place_id=ChIJrTG8QwSZ4jAR7y9dYWUsw_o","เปิดแผนที่") -> เปิดแผนที่ | L32: เปิดให้บริการ (มีเวลาทำการใน Google Maps)
A33: 32 | B33: วัดอรุณราชวรารามราชวรมหาวิหาร | C33: ร้านเครื่องดื่ม | D33: Arun-Cafe | E33: 13.742653 | F33: 100.48749 | G33: 0.17 | H33: 169/3 ถ.อรุณอมรินทร์ วัดอรุณ บางกอกใหญ่ | I33: ทุกวัน 09:00-18:00 | J33: - | K33: =HYPERLINK("https://www.google.com/maps/search/?api=1&query=Arun-Cafe&query_place_id=ChIJhbOGK6qZ4jARpbTx6P5md9s","เปิดแผนที่") -> เปิดแผนที่ | L33: เปิดให้บริการ (มีเวลาทำการใน Google Maps)
A34: 33 | B34: วัดอรุณราชวรารามราชวรมหาวิหาร | C34: ร้านเครื่องดื่ม | D34: gunsbake.cafe | E34: 13.741682 | F34: 100.48632 | G34: 0.33 | H34: 39/7 ถ.วังเดิม วัดอรุณ บางกอกใหญ่ | I34: จ 10:00-18:00 / พ 10:00-16:00 / พฤ 10:00-18:00 / ศ 10:00-16:00 / ส 10:00-18:00 / อา 10:00-17:00 (ปิดวันอังคาร) | J34: +66 86 824 5353 | K34: =HYPERLINK("https://www.google.com/maps/search/?api=1&query=gunsbake.cafe&query_place_id=ChIJwznn8QSZ4jARth7RYPTDmAc","เปิดแผนที่") -> เปิดแผนที่ | L34: เปิดให้บริการ (มีเวลาทำการใน Google Maps)
A35: 34 | B35: วัดอรุณราชวรารามราชวรมหาวิหาร | C35: ร้านของหวาน | D35: Before Sunset | E35: 13.744784 | F35: 100.49129 | G35: 0.32 | H35: 40/1 ซ.ประตูนกยูง พระบรมมหาราชวัง พระนคร | I35: ทุกวัน 13:00-20:00 | J35: - | K35: =HYPERLINK("https://www.google.com/maps/search/?api=1&query=Before%20Sunset&query_place_id=ChIJ28Sybv2Z4jARwGxmuwOJbso","เปิดแผนที่") -> เปิดแผนที่ | L35: เปิดให้บริการ (มีเวลาทำการใน Google Maps)
A36: 35 | B36: วัดอรุณราชวรารามราชวรมหาวิหาร | C36: ร้านของหวาน | D36: Priscilla Ice Cream | E36: 13.746548 | F36: 100.48461 | G36: 0.51 | H36: 59 ซ.ริมคลองมอญ วัดอรุณ บางกอกใหญ่ | I36: จ-พฤ 08:00-18:00 / ศ-ส 08:00-20:00 / อา 08:00-19:00 | J36: +66 83 008 7451 | K36: =HYPERLINK("https://www.google.com/maps/search/?api=1&query=Priscilla%20Ice%20Cream&query_place_id=ChIJ321kK3GZ4jAR2rRWuWXBPMw","เปิดแผนที่") -> เปิดแผนที่ | L36: เปิดให้บริการ (มีเวลาทำการใน Google Maps)
A37: 36 | B37: วัดอรุณราชวรารามราชวรมหาวิหาร | C37: ร้านของหวาน | D37: Ice Therapy (ไอศกรีมเจลาโต้) | E37: 13.741523 | F37: 100.48604 | G37: 0.37 | H37: 105 ถ.วังเดิม วัดอรุณ บางกอกใหญ่ | I37: จ,อ,พฤ-อา 12:00-20:00 (ปิดวันพุธ) | J37: +66 95 775 9794 | K37: =HYPERLINK("https://www.google.com/maps/search/?api=1&query=Ice%20Therapy%20%28%E0%B9%84%E0%B8%AD%E0%B8%A8%E0%B8%81%E0%B8%A3%E0%B8%B5%E0%B8%A1%E0%B9%80%E0%B8%88%E0%B8%A5%E0%B8%B2%E0%B9%82%E0%B8%95%E0%B9%89%29&query_place_id=ChIJJQLvOwCZ4jARUyBcQD86DEY","เปิดแผนที่") -> เปิดแผนที่ | L37: เปิดให้บริการ (มีเวลาทำการใน Google Maps)
A38: 37 | B38: วัดปากน้ำภาษีเจริญ | C38: ร้านอาหาร | D38: ร้านตุ้มอร่อย คาเฟ่ Toomaroi Café | E38: 13.718533 | F38: 100.46772 | G38: 0.46 | H38: 119/18 ถ.เทอดไท ปากคลองภาษีเจริญ ภาษีเจริญ | I38: จ,อ,ศ-อา 09:30-17:30 (ปิดพุธ-พฤหัสบดี) | J38: +66 95 998 7928 | K38: =HYPERLINK(_xlfn._LONGTEXT("https://www.google.com/maps/search/?api=1&query=%E0%B8%A3%E0%B9%89%E0%B8%B2%E0%B8%99%E0%B8%95%E0%B8%B8%E0%B9%89%E0%B8%A1%E0%B8%AD%E0%B8%A3%E0%B9%88%E0%B8%AD%E0%B8%A2%20%E0%B8%84%E0%B8%B2%E0%B9%80%E0%B8%9F%E0%B9%88%20Toomaroi%20Caf%C3%A9&query_place_id=ChI","JT3ZAob-Z4jARZKL_lsJzvVY"),"เปิดแผนที่") -> #VALUE! | L38: เปิดให้บริการ (มีเวลาทำการใน Google Maps)
A39: 38 | B39: วัดปากน้ำภาษีเจริญ | C39: ร้านอาหาร | D39: Hidden Bangkok Bistro | E39: 13.721551 | F39: 100.47194 | G39: 0.17 | H39: 872/8 ซ.เทอดไท 26 ตลาดพลู ธนบุรี | I39: ทุกวัน 09:00-22:00 | J39: +66 90 897 9835 | K39: =HYPERLINK("https://www.google.com/maps/search/?api=1&query=Hidden%20Bangkok%20Bistro&query_place_id=ChIJZ6CYhMaZ4jARJ98e1bZkf5Y","เปิดแผนที่") -> เปิดแผนที่ | L39: เปิดให้บริการ (มีเวลาทำการใน Google Maps)
A40: 39 | B40: วัดปากน้ำภาษีเจริญ | C40: ร้านอาหาร | D40: ฉอเล้ง หมี่กระเฉด ตลาดพลู | E40: 13.720159 | F40: 100.47715 | G40: 0.76 | H40: ซ.เทอดไท 25 ตลาดพลู ธนบุรี | I40: ทุกวัน 11:00-23:00 (เสาร์) | J40: +66 62 569 1465 | K40: =HYPERLINK(_xlfn._LONGTEXT("https://www.google.com/maps/search/?api=1&query=%E0%B8%89%E0%B8%AD%E0%B9%80%E0%B8%A5%E0%B9%89%E0%B8%87%20%E0%B8%AB%E0%B8%A1%E0%B8%B5%E0%B9%88%E0%B8%81%E0%B8%A3%E0%B8%B0%E0%B9%80%E0%B8%89%E0%B8%94%20%E0%B8%95%E0%B8%A5%E0%B8%B2%E0%B8%94%E0%B8%9E%E0%B8%A5%E0","%B8%B9&query_place_id=ChIJ026d7FuY4jARmnM2EpwSY9M"),"เปิดแผนที่") -> #VALUE! | L40: เปิดให้บริการ (มีเวลาทำการใน Google Maps)
...

Sheet แหล่งท่องเที่ยว
A1: ลำดับ | B1: แหล่งท่องเที่ยว | C1: ละติจูด | D1: ลองจิจูด | E1: ร้านอาหาร | F1: ร้านเครื่องดื่ม | G1: ร้านของหวาน | H1: รวม
A2: 1 | B2: SkyWalk King Power Mahanakhon (คิงเพาเวอร์ มหานคร) | C2: 13.72401 | D2: 100.52848 | E2: =COUNTIFS(ร้านใกล้แหล่งท่องเที่ยว!$B:$B,$B2,ร้านใกล้แหล่งท่องเที่ยว!$C:$C,E$1) -> 3 | F2: =COUNTIFS(ร้านใกล้แหล่งท่องเที่ยว!$B:$B,$B2,ร้านใกล้แหล่งท่องเที่ยว!$C:$C,F$1) -> 3 | G2: =COUNTIFS(ร้านใกล้แหล่งท่องเที่ยว!$B:$B,$B2,ร้านใกล้แหล่งท่องเที่ยว!$C:$C,G$1) -> 3 | H2: =SUM(E2:G2) -> 9
A3: 2 | B3: วัดพระศรีรัตนศาสดาราม (วัดพระแก้ว) | C3: 13.7515 | D3: 100.4927 | E3: =COUNTIFS(ร้านใกล้แหล่งท่องเที่ยว!$B:$B,$B3,ร้านใกล้แหล่งท่องเที่ยว!$C:$C,E$1) -> 3 | F3: =COUNTIFS(ร้านใกล้แหล่งท่องเที่ยว!$B:$B,$B3,ร้านใกล้แหล่งท่องเที่ยว!$C:$C,F$1) -> 3 | G3: =COUNTIFS(ร้านใกล้แหล่งท่องเที่ยว!$B:$B,$B3,ร้านใกล้แหล่งท่องเที่ยว!$C:$C,G$1) -> 3 | H3: =SUM(E3:G3) -> 9
A4: 3 | B4: วัดพระเชตุพนวิมลมังคลาราม (วัดโพธิ์) | C4: 13.74642 | D4: 100.49277 | E4: =COUNTIFS(ร้านใกล้แหล่งท่องเที่ยว!$B:$B,$B4,ร้านใกล้แหล่งท่องเที่ยว!$C:$C,E$1) -> 3 | F4: =COUNTIFS(ร้านใกล้แหล่งท่องเที่ยว!$B:$B,$B4,ร้านใกล้แหล่งท่องเที่ยว!$C:$C,F$1) -> 3 | G4: =COUNTIFS(ร้านใกล้แหล่งท่องเที่ยว!$B:$B,$B4,ร้านใกล้แหล่งท่องเที่ยว!$C:$C,G$1) -> 3 | H4: =SUM(E4:G4) -> 9
A5: 4 | B5: วัดอรุณราชวรารามราชวรมหาวิหาร | C5: 13.74387 | D5: 100.48844 | E5: =COUNTIFS(ร้านใกล้แหล่งท่องเที่ยว!$B:$B,$B5,ร้านใกล้แหล่งท่องเที่ยว!$C:$C,E$1) -> 3 | F5: =COUNTIFS(ร้านใกล้แหล่งท่องเที่ยว!$B:$B,$B5,ร้านใกล้แหล่งท่องเที่ยว!$C:$C,F$1) -> 3 | G5: =COUNTIFS(ร้านใกล้แหล่งท่องเที่ยว!$B:$B,$B5,ร้านใกล้แหล่งท่องเที่ยว!$C:$C,G$1) -> 3 | H5: =SUM(E5:G5) -> 9
A6: 5 | B6: วัดปากน้ำภาษีเจริญ | C6: 13.72178 | D6: 100.47036 | E6: =COUNTIFS(ร้านใกล้แหล่งท่องเที่ยว!$B:$B,$B6,ร้านใกล้แหล่งท่องเที่ยว!$C:$C,E$1) -> 3 | F6: =COUNTIFS(ร้านใกล้แหล่งท่องเที่ยว!$B:$B,$B6,ร้านใกล้แหล่งท่องเที่ยว!$C:$C,F$1) -> 3 | G6: =COUNTIFS(ร้านใกล้แหล่งท่องเที่ยว!$B:$B,$B6,ร้านใกล้แหล่งท่องเที่ยว!$C:$C,G$1) -> 3 | H6: =SUM(E6:G6) -> 9
A7: 6 | B7: บรรทัดทอง (ถ.บรรทัดทอง) | C7: 13.7392 | D7: 100.5243 | E7: =COUNTIFS(ร้านใกล้แหล่งท่องเที่ยว!$B:$B,$B7,ร้านใกล้แหล่งท่องเที่ยว!$C:$C,E$1) -> 3 | F7: =COUNTIFS(ร้านใกล้แหล่งท่องเที่ยว!$B:$B,$B7,ร้านใกล้แหล่งท่องเที่ยว!$C:$C,F$1) -> 3 | G7: =COUNTIFS(ร้านใกล้แหล่งท่องเที่ยว!$B:$B,$B7,ร้านใกล้แหล่งท่องเที่ยว!$C:$C,G$1) -> 3 | H7: =SUM(E7:G7) -> 9
A8: 7 | B8: เยาวราช | C8: 13.7397 | D8: 100.5099 | E8: =COUNTIFS(ร้านใกล้แหล่งท่องเที่ยว!$B:$B,$B8,ร้านใกล้แหล่งท่องเที่ยว!$C:$C,E$1) -> 3 | F8: =COUNTIFS(ร้านใกล้แหล่งท่องเที่ยว!$B:$B,$B8,ร้านใกล้แหล่งท่องเที่ยว!$C:$C,F$1) -> 3 | G8: =COUNTIFS(ร้านใกล้แหล่งท่องเที่ยว!$B:$B,$B8,ร้านใกล้แหล่งท่องเที่ยว!$C:$C,G$1) -> 3 | H8: =SUM(E8:G8) -> 9
A9: 8 | B9: คลองบางหลวง (Artist House / ตลาดน้ำคลองบางหลวง ภาษีเจริญ) | C9: 13.7312 | D9: 100.4633 | E9: =COUNTIFS(ร้านใกล้แหล่งท่องเที่ยว!$B:$B,$B9,ร้านใกล้แหล่งท่องเที่ยว!$C:$C,E$1) -> 3 | F9: =COUNTIFS(ร้านใกล้แหล่งท่องเที่ยว!$B:$B,$B9,ร้านใกล้แหล่งท่องเที่ยว!$C:$C,F$1) -> 3 | G9: =COUNTIFS(ร้านใกล้แหล่งท่องเที่ยว!$B:$B,$B9,ร้านใกล้แหล่งท่องเที่ยว!$C:$C,G$1) -> 3 | H9: =SUM(E9:G9) -> 9
A10: 9 | B10: ย่านพระอาทิตย์ (ถ.พระอาทิตย์ บางลำพู) | C10: 13.7632 | D10: 100.4945 | E10: =COUNTIFS(ร้านใกล้แหล่งท่องเที่ยว!$B:$B,$B10,ร้านใกล้แหล่งท่องเที่ยว!$C:$C,E$1) -> 3 | F10: =COUNTIFS(ร้านใกล้แหล่งท่องเที่ยว!$B:$B,$B10,ร้านใกล้แหล่งท่องเที่ยว!$C:$C,F$1) -> 3 | G10: =COUNTIFS(ร้านใกล้แหล่งท่องเที่ยว!$B:$B,$B10,ร้านใกล้แหล่งท่องเที่ยว!$C:$C,G$1) -> 3 | H10: =SUM(E10:G10) -> 9
A11: 10 | B11: หอศิลปวัฒนธรรมแห่งกรุงเทพมหานคร (BACC) | C11: 13.74673 | D11: 100.53022 | E11: =COUNTIFS(ร้านใกล้แหล่งท่องเที่ยว!$B:$B,$B11,ร้านใกล้แหล่งท่องเที่ยว!$C:$C,E$1) -> 3 | F11: =COUNTIFS(ร้านใกล้แหล่งท่องเที่ยว!$B:$B,$B11,ร้านใกล้แหล่งท่องเที่ยว!$C:$C,F$1) -> 3 | G11: =COUNTIFS(ร้านใกล้แหล่งท่องเที่ยว!$B:$B,$B11,ร้านใกล้แหล่งท่องเที่ยว!$C:$C,G$1) -> 3 | H11: =SUM(E11:G11) -> 9
A12: 11 | B12: Asiatique The Riverfront | C12: 13.70442 | D12: 100.50327 | E12: =COUNTIFS(ร้านใกล้แหล่งท่องเที่ยว!$B:$B,$B12,ร้านใกล้แหล่งท่องเที่ยว!$C:$C,E$1) -> 3 | F12: =COUNTIFS(ร้านใกล้แหล่งท่องเที่ยว!$B:$B,$B12,ร้านใกล้แหล่งท่องเที่ยว!$C:$C,F$1) -> 3 | G12: =COUNTIFS(ร้านใกล้แหล่งท่องเที่ยว!$B:$B,$B12,ร้านใกล้แหล่งท่องเที่ยว!$C:$C,G$1) -> 3 | H12: =SUM(E12:G12) -> 9
A13: 12 | B13: ท้องฟ้าจำลองกรุงเทพ (เอกมัย) | C13: 13.71954 | D13: 100.58278 | E13: =COUNTIFS(ร้านใกล้แหล่งท่องเที่ยว!$B:$B,$B13,ร้านใกล้แหล่งท่องเที่ยว!$C:$C,E$1) -> 3 | F13: =COUNTIFS(ร้านใกล้แหล่งท่องเที่ยว!$B:$B,$B13,ร้านใกล้แหล่งท่องเที่ยว!$C:$C,F$1) -> 3 | G13: =COUNTIFS(ร้านใกล้แหล่งท่องเที่ยว!$B:$B,$B13,ร้านใกล้แหล่งท่องเที่ยว!$C:$C,G$1) -> 3 | H13: =SUM(E13:G13) -> 9
... A20: 19 | B20: สะพานพระพุทธยอดฟ้า (สะพานพุทธ) | C20: 13.73928 | D20: 100.4976 | E20: =COUNTIFS(ร้านใกล้แหล่งท่องเที่ยว!$B:$B,$B20,ร้านใกล้แหล่งท่องเที่ยว!$C:$C,E$1) -> 3 | F20: =COUNTIFS(ร้านใกล้แหล่งท่องเที่ยว!$B:$B,$B20,ร้านใกล้แหล่งท่องเที่ยว!$C:$C,F$1) -> 3 | G20: =COUNTIFS(ร้านใกล้แหล่งท่องเที่ยว!$B:$B,$B20,ร้านใกล้แหล่งท่องเที่ยว!$C:$C,G$1) -> 3 | H20: =SUM(E20:G20) -> 9
B21: รวมทั้งหมด | E21: =SUM(E2:E20) -> 57 | F21: =SUM(F2:F20) -> 57 | G21: =SUM(G2:G20) -> 57 | H21: =SUM(H2:H20) -> 171

Sheet หมายเหตุ
A1: หัวข้อ | B1: รายละเอียด
A2: ที่มาข้อมูล | B2: ข้อมูลร้านค้า พิกัด เวลาทำการ เบอร์โทร และรหัสสถานที่ (place_id) ดึงจาก Google Places (Google Maps) เมื่อวันที่ 3 ต.ค. 2569
A3: นิยามคำว่า "เปิดให้บริการ" | B3: ร้านมีสถานะประกอบกิจการอยู่ใน Google Maps (ไม่ใช่ปิดถาวร/ปิดชั่วคราว) และมีวัน-เวลาทำการระบุไว้ ไม่ได้โทรยืนยันกับร้านรายร้าน แนะนำให้เช็กเวลาล่าสุดจากลิงก์ก่อนเดินทาง
A4: ร้านที่เปิดเฉพาะบางวัน | B4: ดูคอลัมน์ "วัน-เวลาเปิดให้บริการ" เช่น ร้านปิดวันจันทร์/อังคาร/พุธ/อาทิตย์ ร้านในตลาดจตุจักรบางร้านเปิดเฉพาะเสาร์-อาทิตย์ และบางร้านเปิดเฉพาะช่วงเย็น
A5: พิกัด | B5: ละติจูด/ลองจิจูดของแต่ละร้านมาจาก Google Maps (WGS84) ส่วนพิกัดแหล่งท่องเที่ยวอยู่ในชีต "แหล่งท่องเที่ยว"
A6: ระยะห่าง | B6: คำนวณเป็นระยะทางเส้นตรง (Haversine) จากจุดอ้างอิงแหล่งท่องเที่ยวถึงร้าน ไม่ใช่ระยะเดินจริง
A7: ลิงก์ | B7: ลิงก์ Google Maps สร้างจากรหัสสถานที่ของแต่ละร้าน คลิกแล้วเปิดตำแหน่งร้านนั้นโดยตรง
A8: คลองบางหลวง | B8: ตีความเป็นย่านคลองบางหลวง-บ้านศิลปิน/ตลาดน้ำคลองบางหลวง (ซ.เพชรเกษม 20 เขตภาษีเจริญ) หากหมายถึงจุดอื่นของคลองบางหลวง (เช่น ฝั่งบางกอกน้อย) แจ้งได้เพื่อค้นหาใหม่
A9: สวนสยาม | B9: Google Maps แสดงชื่อ Siam Amazing Park (เขตคันนายาว) ใช้พิกัดนั้นเป็นจุดอ้างอิง
A10: เยาวราช | B10: ผู้ใช้ระบุซ้ำ 2 ครั้งในรายการ นับเป็นแหล่งเดียว รวมแหล่งท่องเที่ยวทั้งหมด 19 แห่ง
A11: ห้างสรรพสินค้า | B11: ร้านใน Siam Paragon / ICONSIAM อยู่ภายในห้างหรือบริเวณรอบห้าง ระยะเส้นตรงบางร้านอยู่ห่าง 0.5-1.5 กม.
