Workbook

Sheet คู่มือ
A1: คู่มือไฟล์สถานที่กรุงเทพฯ
A2: ข้อมูลจากไฟล์ของ Nirapada จัดใหม่ให้ตรง schema ใน docs/DATA.md · 1 แถว = 1 Place
A4: สีหัวคอลัมน์ในชีต places
A5: ข้อมูลหลัก | B5: id, category, name, area
A6: พิกัด | B6: lat, lng
A7: การจัดอันดับ | B7: tags, priceLevel, rating
A8: เวลาเปิด | B8: mon, tue, wed, thu, fri, sat, sun
A9: รายละเอียด | B9: dwellMinutes, entranceFee, shortDescription, breakfastIncluded
A10: ตรวจสอบ | B10: mealSuitable, needsReview, note
A11: อ้างอิง (ไม่เข้า JSON) | B11: sourceType, nearAttraction, distanceKm, googleName, googleReviews, googleCategories, …
A12: แถวสีเหลือง | B12: มีค่าในคอลัมน์ needsReview ต้องตรวจก่อนนำเข้า
A14: วิธีกรอกและที่มาข้อมูล
A15: การนำเข้า | B15: แถว 1 = ชื่อ key ใน JSON (ห้ามแก้) แถว 2 = คำอธิบายภาษาไทย ข้อมูลเริ่มแถว 3 คอลัมน์กลุ่ม "อ้างอิง" ไม่เข้า JSON
A16: tags | B16: คั่นด้วยจุลภาค ใช้ได้เฉพาะ: adventure, artCulture, beach, cafe, family, localFood, nature, nightlife, seafood, shopping, templeHistory, viewpoint, wellness
A17: mon … sun | B17: รูปแบบ HH:MM-HH:MM · ช่องว่าง (สีเทา) = ปิดวันนั้น · ปิดหลังเที่ยงคืนให้เขียนเกิน 24:00 เช่น 17:30-25:30 · เปิดตลอดวัน = 00:00-24:00
A18: priceLevel | B18: ร้าน: 1 ≤150 · 2 ~150–400 · 3 ~400–1,000 · 4 >1,000 บาทต่อคนต่อมื้อ (สีทองเข้ม = แพง) เป็นค่าประมาณ ยังไม่มีข้อมูลราคาจาก Google
A19: rating, เวลาเปิด | B19: ดึงจาก Google Maps วันที่ 4 ต.ค. 2569 ด้วย place_id ของแต่ละร้าน · rating ≥ 4.5 สีเขียว, < 4.0 สีแดง
A20: entranceFee | B20: ใช้ราคาชาวต่างชาติผู้ใหญ่ ตามที่ bangkok.json เดิมใช้ (วังหลวง 500, วัดโพธิ์ 300) ราคาคนไทยอยู่ในคอลัมน์ entranceFeeThai
A21: mealSuitable | B21: Y = ใช้เป็นมื้อกลางวัน/เย็นได้ (planner ใช้ restaurant เฉพาะช่วงมื้อหลัก) · N = ร้านเครื่องดื่ม-ของหวาน แนะนำให้นำเข้าเฉพาะ Y ไปก่อน
A22: สิ่งที่แก้จากไฟล์เดิม | B22: 1) เวลาเปิด 66 แถวที่เขียน "ทุกวัน … (เสาร์)" เดิมเช็กแค่วันเสาร์ ตอนนี้เป็นเวลาจริงรายวันจาก Google 2) เวลาปิดหลังเที่ยงคืนเขียนแบบ 26:00 3) ร้านที่เปิด 2 ช่วงใส่ช่วงรวมและจดใน note 4) ลิงก์เป็น URL ธรรมดา + แยก place_id 5) เบอร์ "-" เป็นช่องว่าง 6) ตัดคอลัมน์สถานะที่ซ้ำกันทุกแถว
A23: id ที่ชนกับของเดิม | B23: grand-palace, wat-pho, wat-arun, chatuchak ใช้ id เดียวกับใน bangkok.json ให้แทนที่ของเดิม ไม่ใช่เพิ่มซ้ำ
A24: ยังขาดตามเป้า #21 | B24: attraction มี 19 (เป้า ≥ 25) และยังไม่มี accommodation (เป้า ≥ 8) เพิ่มแถวในชีต places ได้ โดยเปลี่ยน category
A25: ต้นฉบับ | B25: ชีต "ต้นฉบับ_…" คือข้อมูลเดิมของ Nirapada ไม่ได้แก้เนื้อหา

Sheet places
A1: id | B1: category | C1: name | D1: area | E1: lat | F1: lng | G1: tags | H1: priceLevel | I1: rating | J1: mon | K1: tue | L1: wed | M1: thu | N1: fri | O1: sat | P1: sun | Q1: dwellMinutes | R1: entranceFee | S1: shortDescription | T1: breakfastIncluded | U1: mealSuitable | V1: needsReview | W1: note | X1: sourceType | Y1: nearAttraction | Z1: distanceKm | AA1: googleName | AB1: googleReviews | AC1: googleCategories | AD1: hoursSource | AE1: hoursOriginal | AF1: priceLevelSource | AG1: entranceFeeThai | AH1: address | AI1: phone | AJ1: googlePlaceId | AK1: googleMapsUrl
A2: รหัส (ห้ามซ้ำ/ห้ามเปลี่ยน) | B2: หมวด | C2: ชื่อ | D2: ย่าน | E2: ละติจูด | F2: ลองจิจูด | G2: แท็ก (คั่นด้วย ,) | H2: ระดับราคา 1–4 | I2: คะแนน Google | J2: จันทร์ | K2: อังคาร | L2: พุธ | M2: พฤหัสฯ | N2: ศุกร์ | O2: เสาร์ | P2: อาทิตย์ | Q2: เวลาที่อยู่ (นาที) | R2: ค่าเข้า (บาท/คน) | S2: คำอธิบายสั้น (≤120 ตัวอักษร) | T2: รวมอาหารเช้า (ที่พักเท่านั้น) | U2: ใช้เป็นมื้อหลักได้ | V2: ต้องตรวจ | W2: หมายเหตุ | X2: ประเภทเดิม | Y2: ใกล้แหล่งท่องเที่ยว | Z2: ระยะ (กม.) | AA2: ชื่อใน Google | AB2: จำนวนรีวิว | AC2: หมวดใน Google | AD2: ที่มาเวลาเปิด | AE2: เวลาเปิด (ตารางเดิม) | AF2: ที่มาระดับราคา | AG2: ค่าเข้าคนไทย | AH2: ที่อยู่ | AI2: เบอร์โทร | AJ2: Google place_id | AK2: ลิงก์ Google Maps
A3: bangkok-attraction-asiatique-the-riverfront | B3: attraction | C3: Asiatique The Riverfront | D3: ริมแม่น้ำเจ้าพระยา | E3: 13.70442 | F3: 100.50327 | G3: shopping,nightlife,viewpoint,family | H3: 2 | J3: 16:00-24:00 | K3: 16:00-24:00 | L3: 16:00-24:00 | M3: 16:00-24:00 | N3: 16:00-24:00 | O3: 16:00-24:00 | P3: 16:00-24:00 | Q3: 120 | R3: 0 | S3: ตลาดกลางคืนริมแม่น้ำในโกดังเก่า มีร้านค้า ร้านอาหาร และชิงช้าสวรรค์ | V3: ไม่มี rating | W3: Google ไม่คืนข้อมูล เวลาเปิดเป็นค่าประมาณ (บางโซนเปิดตั้งแต่ 11:00) / ไม่มี rating | X3: แหล่งท่องเที่ยว | AD3: ประมาณการ/แหล่งข้อมูลอื่น | AF3: ประมาณการจากค่าเข้า | AG3: 0 | AK3: เปิดแผนที่ ↗
A4: bangkok-attraction-bacc | B4: attraction | C4: หอศิลปวัฒนธรรมแห่งกรุงเทพมหานคร (BACC) | D4: สยาม/ปทุมวัน | E4: 13.74673 | F4: 100.53022 | G4: artCulture | H4: 1 | I4: 4.6 | K4: 10:00-20:00 | L4: 10:00-20:00 | M4: 10:00-20:00 | N4: 10:00-20:00 | O4: 10:00-20:00 | P4: 10:00-20:00 | Q4: 90 | R4: 0 | S4: หอศิลป์ร่วมสมัยใจกลางสยาม จัดนิทรรศการหมุนเวียน เข้าชมฟรี | W4: ปิดวันจันทร์ | X4: แหล่งท่องเที่ยว | AA4: หอศิลปวัฒนธรรมแห่งกรุงเทพมหานคร | AC4: ศูนย์งานศิลปะ, ห้องแสดงงานศิลปะ, สถานที่ท่องเที่ยว | AD4: แก้จาก Google (ดูหมายเหตุ) | AF4: ประมาณการจากค่าเข้า | AG4: 0 | AH4: หอศิลปวัฒนธรรมแห่งกรุงเทพมหานคร 939 ถ. พระรามที่ 1 แขวงวังใหม่ เขตปทุมวัน กรุงเทพมหานคร 10330 | AJ4: ChIJfWxvUM2e4jARCxWWp4sC0B4 | AK4: เปิดแผนที่ ↗
A5: bangkok-attraction-bangkok-planetarium | B5: attraction | C5: ท้องฟ้าจำลองกรุงเทพ (เอกมัย) | D5: เอกมัย | E5: 13.71954 | F5: 100.58278 | G5: family,artCulture | H5: 1 | I5: 4.2 | K5: 09:00-16:00 | L5: 09:00-16:00 | M5: 09:00-16:00 | N5: 09:00-16:00 | O5: 09:00-16:00 | P5: 09:00-16:00 | Q5: 90 | R5: 200 | S5: ท้องฟ้าจำลองแห่งแรกของไทย มีการฉายดาวและนิทรรศการวิทยาศาสตร์ | V5: ตรวจเวลาเปิด | W5: ปิดวันจันทร์ / มีข่าวปิดปรับปรุงช่วงปี 2569 ต้องเช็กว่าเปิดแล้วหรือยังก่อนใช้ | X5: แหล่งท่องเที่ยว | AA5: ศูนย์ส่งเสริมและพัฒนาการเรียนรู้ทางวิทยาศาสตร์ (ท้องฟ้าจำลองกรุงเทพ) | AC5: พิพิธภัณฑ์วิทยาศาสตร์, ท้องฟ้าจำลอง, สถานที่ท่องเที่ยว | AD5: แก้จาก Google (ดูหมายเหตุ) | AF5: ประมาณการจากค่าเข้า | AG5: 100 | AH5: ศูนย์ส่งเสริมและพัฒนาการเรียนรู้ทางวิทยาศาสตร์ (ท้องฟ้าจำลองกรุงเทพ) 928 ถ. สุขุมวิท แขวงพระโขนง เขตคลองเตย กรุงเทพมหานคร 10110 | AJ5: ChIJnUa-d6Wf4jARp1M-LNKpKCw | AK5: เปิดแผนที่ ↗
A6: bangkok-attraction-banthat-thong-road | B6: attraction | C6: บรรทัดทอง (ถ.บรรทัดทอง) | D6: บรรทัดทอง | E6: 13.7392 | F6: 100.5243 | G6: localFood,nightlife | H6: 1 | J6: 16:00-24:00 | K6: 16:00-24:00 | L6: 16:00-24:00 | M6: 16:00-24:00 | N6: 16:00-24:00 | O6: 16:00-24:00 | P6: 16:00-24:00 | Q6: 90 | R6: 0 | S6: ถนนสตรีทฟู้ดย่านสามย่าน-จุฬาฯ ร้านอาหารและของหวานเปิดถึงดึก | V6: ไม่มี rating; ตรวจเวลาเปิด | W6: เป็นถนน ไม่มีเวลาทำการทางการ ใช้ช่วงที่ร้านส่วนใหญ่เปิด (ประมาณการ) / Google ไม่มี rating | X6: แหล่งท่องเที่ยว | AA6: ถนน บรรทัดทอง | AD6: ประมาณการ/แหล่งข้อมูลอื่น | AF6: ประมาณการจากค่าเข้า | AG6: 0 | AH6: ถนน บรรทัดทอง กรุงเทพมหานคร | AJ6: ChIJCeI1ky2Z4jARzlbzs6UHjXs | AK6: เปิดแผนที่ ↗
A7: bangkok-attraction-benjakitti-park | B7: attraction | C7: สวนเบญจกิติ | D7: สุขุมวิท | E7: 13.72923 | F7: 100.55873 | G7: nature,viewpoint | H7: 1 | I7: 4.6 | J7: 04:30-22:00 | K7: 04:30-22:00 | L7: 04:30-22:00 | M7: 04:30-22:00 | N7: 04:30-22:00 | O7: 04:30-22:00 | P7: 04:30-22:00 | Q7: 90 | R7: 0 | S7: สวนป่ากลางเมืองย่านอโศก มีทางเดินลอยฟ้าชมสวนและบึงน้ำ | X7: แหล่งท่องเที่ยว | AA7: สวนเบญจกิติ | AB7: 11276 | AC7: สวนสาธารณะของเมือง | AD7: Google Maps (รายวัน) | AF7: ประมาณการจากค่าเข้า | AG7: 0 | AH7: สวนเบญจกิติ ถ. รัชดาภิเษก แขวงคลองเตย เขตคลองเตย กรุงเทพมหานคร 10110 | AJ7: ChIJmfMfvBuf4jAR9rugvZd5Lyc | AK7: เปิดแผนที่ ↗
A8: bangkok-attraction-chatuchak | B8: attraction | C8: ตลาดจตุจักร | D8: จตุจักร | E8: 13.79978 | F8: 100.55042 | G8: shopping,localFood | H8: 1 | I8: 4.4 | O8: 09:00-18:00 | P8: 09:00-18:00 | Q8: 180 | R8: 0 | S8: ตลาดนัดสุดสัปดาห์ขนาดใหญ่ ร้านค้ากว่าหมื่นร้าน | W8: id ตรงกับที่มีอยู่แล้วใน bangkok.json / Google ไม่คืนข้อมูล ใช้ rating และเวลาจากของเดิม | X8: แหล่งท่องเที่ยว | AD8: ประมาณการ/แหล่งข้อมูลอื่น | AF8: ประมาณการจากค่าเข้า | AG8: 0 | AK8: เปิดแผนที่ ↗
A9: bangkok-attraction-grand-palace | B9: attraction | C9: วัดพระศรีรัตนศาสดาราม (วัดพระแก้ว) | D9: เกาะรัตนโกสินทร์ | E9: 13.7515 | F9: 100.4927 | G9: templeHistory,artCulture | H9: 2 | I9: 4.6 | J9: 08:30-15:30 | K9: 08:30-15:30 | L9: 08:30-15:30 | M9: 08:30-15:30 | N9: 08:30-15:30 | O9: 08:30-15:30 | P9: 08:30-15:30 | Q9: 120 | R9: 500 | S9: พระราชวังและวัดพระแก้ว สถาปัตยกรรมไทยที่งดงามที่สุดแห่งหนึ่ง | W9: id ตรงกับที่มีอยู่แล้วใน bangkok.json (แทนที่ของเดิม) / คนไทยเข้าฟรี | X9: แหล่งท่องเที่ยว | AA9: พระบรมมหาราชวัง | AB9: 80321 | AC9: ปราสาท, สถานที่สำคัญทางวัฒนธรรม, สถานที่สำคัญทางประวัติศาสตร์, อุทยาน, สถานที่ท่องเที่ยว | AD9: Google Maps (รายวัน) | AF9: ประมาณการจากค่าเข้า | AG9: 0 | AH9: พระบรมมหาราชวัง แขวงพระบรมมหาราชวัง เขตพระนคร กรุงเทพมหานคร 10200 | AJ9: ChIJPzZsMU6Z4jARQUzvk913bCo | AK9: เปิดแผนที่ ↗
A10: bangkok-attraction-iconsiam | B10: attraction | C10: ไอคอนสยาม | D10: ริมแม่น้ำเจ้าพระยา | E10: 13.72623 | F10: 100.51045 | G10: shopping,viewpoint,family | H10: 2 | I10: 4.7 | J10: 10:00-22:00 | K10: 10:00-22:00 | L10: 10:00-22:00 | M10: 10:00-22:00 | N10: 10:00-22:00 | O10: 10:00-22:00 | P10: 10:00-22:00 | Q10: 150 | R10: 0 | S10: ห้างริมแม่น้ำเจ้าพระยา มีสุขสยามจำลองตลาดไทยสี่ภาค และร้านอาหารมากมาย | X10: แหล่งท่องเที่ยว | AA10: ไอคอนสยาม | AB10: 60286 | AC10: ศูนย์การค้า | AD10: Google Maps (รายวัน) | AF10: ประมาณการจากค่าเข้า | AG10: 0 | AH10: ไอคอนสยาม 299 ถ. เจริญนคร แขวงคลองต้นไทร คลองสาน กรุงเทพมหานคร 10600 | AJ10: ChIJFRjwgc2Z4jAR9JIadoa9YBY | AK10: เปิดแผนที่ ↗
A11: bangkok-attraction-khlong-bang-luang-artist-house | B11: attraction | C11: คลองบางหลวง (Artist House / ตลาดน้ำคลองบางหลวง ภาษีเจริญ) | D11: คลองบางหลวง | E11: 13.7312 | F11: 100.4633 | G11: artCulture,cafe | H11: 1 | I11: 4.6 | J11: 10:00-18:00 | K11: 10:00-18:00 | L11: 10:00-18:00 | M11: 10:00-18:00 | N11: 10:00-18:00 | O11: 10:00-19:00 | P11: 10:00-18:00 | Q11: 90 | R11: 0 | S11: บ้านไม้เก่าริมคลองบางหลวง มีแกลเลอรีศิลปะ คาเฟ่ และการแสดงหุ่นละครเล็ก | X11: แหล่งท่องเที่ยว | AA11: บ้านศิลปินคลองบางหลวง | AB11: 3347 | AC11: สถานที่ท่องเที่ยว, คาเฟ่ศิลปะ, ห้องแสดงงานศิลปะ, ร้านกาแฟ, ร้านของที่ระลึก | AD11: Google Maps (รายวัน) | AF11: ประมาณการจากค่าเข้า | AG11: 0 | AH11: บ้านศิลปินคลองบางหลวง 309 ถ. เพชรเกษม แขวงคูหาสวรรค์ เขตภาษีเจริญ กรุงเทพมหานคร 10160 | AJ11: ChIJF6uVAzt9HTEROKM0WKZMU7M | AK11: เปิดแผนที่ ↗
A12: bangkok-attraction-mahanakhon-skywalk | B12: attraction | C12: SkyWalk King Power Mahanakhon (คิงเพาเวอร์ มหานคร) | D12: สีลม | E12: 13.72401 | F12: 100.52848 | G12: viewpoint,nightlife | H12: 3 | I12: 4.7 | J12: 10:00-19:00 | K12: 10:00-19:00 | L12: 10:00-19:00 | M12: 10:00-19:00 | N12: 10:00-19:00 | O12: 10:00-19:00 | P12: 10:00-19:00 | Q12: 90 | R12: 880 | S12: จุดชมวิวพื้นกระจกชั้น 78 ตึกคิงเพาเวอร์ มหานคร หนึ่งในตึกที่สูงที่สุดของกรุงเทพฯ | W12: ค่าเข้า 880 บาทคือรอบกลางวัน รอบพระอาทิตย์ตก 1,080 บาท / Google คืนเวลาของตัวตึก (10:00–24:00) จึงใช้เวลาเปิด SkyWalk แทน | X12: แหล่งท่องเที่ยว | AA12: ตึกคิงเพาเวอร์ มหานคร | AC12: สถานที่ท่องเที่ยว, บาร์, ร้านค้า | AD12: แก้จาก Google (ดูหมายเหตุ) | AF12: ประมาณการจากค่าเข้า | AG12: 880 | AH12: ตึกคิงเพาเวอร์ มหานคร 114 ถนน นราธิวาสราชนครินทร์ แขวงสีลม เขตบางรัก กรุงเทพมหานคร 10500 | AJ12: ChIJGzV2mdKY4jARdIb62T7BoE4 | AK12: เปิดแผนที่ ↗
A13: bangkok-attraction-memorial-bridge | B13: attraction | C13: สะพานพระพุทธยอดฟ้า (สะพานพุทธ) | D13: ปากคลองตลาด | E13: 13.73928 | F13: 100.4976 | G13: viewpoint,templeHistory | H13: 1 | I13: 4.7 | J13: 00:00-24:00 | K13: 00:00-24:00 | L13: 00:00-24:00 | M13: 00:00-24:00 | N13: 00:00-24:00 | O13: 00:00-24:00 | P13: 00:00-24:00 | Q13: 30 | R13: 0 | S13: สะพานข้ามแม่น้ำเจ้าพระยาเก่าแก่ สร้างสมัยรัชกาลที่ 7 ใกล้ตลาดดอกไม้ปากคลองตลาด | X13: แหล่งท่องเที่ยว | AA13: สะพานพระพุทธยอดฟ้า | AB13: 403 | AC13: สะพาน | AD13: Google Maps (รายวัน) | AF13: ประมาณการจากค่าเข้า | AG13: 0 | AH13: PFQX+P29 สะพานพระพุทธยอดฟ้า สะพานพุทธยอดฟ้าจุฬาโลกมหาราช, แขวงวังบูรพาภิรมย์ เขตพระนคร กรุงเทพมหานคร 10600 | AJ13: ChIJEcUU04SZ4jARfyNZ0JzFzng | AK13: เปิดแผนที่ ↗
A14: bangkok-attraction-phra-athit-road | B14: attraction | C14: ย่านพระอาทิตย์ (ถ.พระอาทิตย์ บางลำพู) | D14: บางลำพู | E14: 13.7632 | F14: 100.4945 | G14: localFood,nightlife,templeHistory | H14: 1 | J14: 00:00-24:00 | K14: 00:00-24:00 | L14: 00:00-24:00 | M14: 00:00-24:00 | N14: 00:00-24:00 | O14: 00:00-24:00 | P14: 00:00-24:00 | Q14: 90 | R14: 0 | S14: ถนนเลียบแม่น้ำย่านบางลำพู มีป้อมพระสุเมรุ สวนสันติชัยปราการ และร้านอาหาร-บาร์ | V14: ไม่มี rating | W14: เป็นถนนสาธารณะ ใส่เปิดตลอดวัน / Google ไม่มี rating | X14: แหล่งท่องเที่ยว | AA14: ถนน พระอาทิตย์ | AD14: ประมาณการ/แหล่งข้อมูลอื่น | AF14: ประมาณการจากค่าเข้า | AG14: 0 | AH14: ถนน พระอาทิตย์ เขตพระนคร กรุงเทพมหานคร 10200 | AJ14: ChIJpRU2WHKZ4jARaOpvlk-0OVc | AK14: เปิดแผนที่ ↗
A15: bangkok-attraction-siam-amazing-park | B15: attraction | C15: สวนสยาม (Siam Amazing Park) | D15: คันนายาว | E15: 13.80629 | F15: 100.69253 | G15: family,adventure | H15: 3 | I15: 4.2 | J15: 10:00-18:00 | K15: 10:00-18:00 | L15: 10:00-18:00 | M15: 10:00-18:00 | N15: 10:00-18:00 | O15: 10:00-18:00 | P15: 10:00-18:00 | Q15: 300 | R15: 1000 | S15: สวนสนุกและสวนน้ำขนาดใหญ่ย่านคันนายาว มีเครื่องเล่นหลากหลาย | W15: ค่าเข้า = บัตร Adventure Pass ผู้ใหญ่หน้าเคาน์เตอร์ (ออนไลน์มักถูกกว่า) | X15: แหล่งท่องเที่ยว | AA15: สยามอะเมซิ่งพาร์ค | AB15: 17431 | AC15: สวนสนุก, สถานที่ท่องเที่ยว | AD15: ประมาณการ/แหล่งข้อมูลอื่น | AF15: ประมาณการจากค่าเข้า | AG15: 1000 | AH15: สยามอะเมซิ่งพาร์ค 203 ถ. สวนสยาม แขวงคันนายาว เขตคันนายาว กรุงเทพมหานคร 10230 | AJ15: ChIJrc78zJBjHTERdLG8EciM5Qs | AK15: เปิดแผนที่ ↗
A16: bangkok-attraction-siam-paragon | B16: attraction | C16: สยามพารากอน | D16: สยาม/ปทุมวัน | E16: 13.74617 | F16: 100.53486 | G16: shopping,family | H16: 2 | J16: 10:00-22:00 | K16: 10:00-22:00 | L16: 10:00-22:00 | M16: 10:00-22:00 | N16: 10:00-22:00 | O16: 10:00-22:00 | P16: 10:00-22:00 | Q16: 120 | R16: 0 | S16: ห้างสรรพสินค้าใหญ่ใจกลางสยาม มีร้านค้า ร้านอาหาร และอควาเรียม | V16: ไม่มี rating | W16: Google ไม่คืนข้อมูล / ไม่มี rating | X16: แหล่งท่องเที่ยว | AD16: ประมาณการ/แหล่งข้อมูลอื่น | AF16: ประมาณการจากค่าเข้า | AG16: 0 | AK16: เปิดแผนที่ ↗
A17: bangkok-attraction-suan-rot-fai | B17: attraction | C17: สวนวชิรเบญจทัศ (สวนรถไฟ) | D17: จตุจักร | E17: 13.8137 | F17: 100.5536 | G17: nature,family | H17: 1 | I17: 4.6 | J17: 04:30-21:00 | K17: 04:30-21:00 | L17: 04:30-21:00 | M17: 04:30-21:00 | N17: 04:30-21:00 | O17: 04:30-21:00 | P17: 04:30-21:00 | Q17: 90 | R17: 0 | S17: สวนสาธารณะขนาดใหญ่ย่านจตุจักร มีเส้นทางปั่นจักรยานและสวนผีเสื้อ | X17: แหล่งท่องเที่ยว | AA17: สวนวชิรเบญจทัศ | AB17: 8692 | AC17: สวนสาธารณะ, สวนสาธารณะของเมือง | AD17: Google Maps (รายวัน) | AF17: ประมาณการจากค่าเข้า | AG17: 0 | AH17: สวนวชิรเบญจทัศ ถนน กำแพงเพชร 3 แขวง ลาดยาว เขตจตุจักร กรุงเทพมหานคร 10900 | AJ17: ChIJTw-JsUKc4jAREpXc3JmuyAE | AK17: เปิดแผนที่ ↗
A18: bangkok-attraction-wat-arun | B18: attraction | C18: วัดอรุณราชวรารามราชวรมหาวิหาร | D18: ริมแม่น้ำเจ้าพระยา | E18: 13.74387 | F18: 100.48844 | G18: templeHistory,viewpoint | H18: 1 | I18: 4.7 | J18: 08:00-18:00 | K18: 08:00-18:00 | L18: 08:00-18:00 | M18: 08:00-18:00 | N18: 08:00-18:00 | O18: 08:00-18:00 | P18: 08:00-18:00 | Q18: 60 | R18: 200 | S18: พระปรางค์ริมแม่น้ำเจ้าพระยา สวยที่สุดช่วงเย็น | W18: id ตรงกับที่มีอยู่แล้วใน bangkok.json / คนไทยเข้าฟรี | X18: แหล่งท่องเที่ยว | AA18: วัดอรุณราชวรารามราชวรมหาวิหาร | AB18: 45345 | AC18: วัด | AD18: Google Maps (รายวัน) | AF18: ประมาณการจากค่าเข้า | AG18: 0 | AH18: วัดอรุณราชวรารามราชวรมหาวิหาร 158 ถนน วังเดิม แขวงวัดอรุณ เขตบางกอกใหญ่ กรุงเทพมหานคร 10600 | AJ18: ChIJaSv_6gaZ4jARnbiUVn6Z_YY | AK18: เปิดแผนที่ ↗
A19: bangkok-attraction-wat-paknam-phasi-charoen | B19: attraction | C19: วัดปากน้ำภาษีเจริญ | D19: ตลาดพลู-ภาษีเจริญ | E19: 13.72178 | F19: 100.47036 | G19: templeHistory,viewpoint | H19: 1 | I19: 4.7 | J19: 08:00-18:00 | K19: 08:00-18:00 | L19: 08:00-18:00 | M19: 08:00-18:00 | N19: 08:00-18:00 | O19: 08:00-18:00 | P19: 08:00-18:00 | Q19: 60 | R19: 0 | S19: วัดริมคลองภาษีเจริญ มีมหาเจดีย์สีขาวสูง ชั้นบนสุดมีเจดีย์แก้วสีเขียว | V19: ตรวจเวลาเปิด | W19: Google ระบุเปิด 24 ชม. แต่ใช้ 08:00–18:00 ตามเวลาเข้าชมพระมหาเจดีย์โดยประมาณ ควรตรวจสอบ | X19: แหล่งท่องเที่ยว | AA19: วัดปากน้ำภาษีเจริญ | AB19: 12132 | AC19: วัด | AD19: แก้จาก Google (ดูหมายเหตุ) | AF19: ประมาณการจากค่าเข้า | AG19: 0 | AH19: 300 วัดปากน้ำภาษีเจริญ ซอย รัชมงคลประสาธน์ แขวงปากคลองภาษีเจริญ เขตภาษีเจริญ กรุงเทพมหานคร 10160 | AJ19: ChIJvwXXwEWY4jARC2dj117syBA | AK19: เปิดแผนที่ ↗
A20: bangkok-attraction-wat-pho | B20: attraction | C20: วัดพระเชตุพนวิมลมังคลาราม (วัดโพธิ์) | D20: เกาะรัตนโกสินทร์ | E20: 13.74642 | F20: 100.49277 | G20: templeHistory,wellness | H20: 1 | I20: 4.7 | J20: 08:00-18:30 | K20: 08:00-18:30 | L20: 08:00-18:30 | M20: 08:00-18:30 | N20: 08:00-18:30 | O20: 08:00-18:30 | P20: 08:00-18:30 | Q20: 90 | R20: 300 | S20: พระพุทธไสยาสน์องค์ใหญ่และต้นตำรับนวดแผนไทย | W20: id ตรงกับที่มีอยู่แล้วใน bangkok.json / Google ไม่คืนข้อมูล ใช้ rating และเวลาจาก bangkok.json เดิม / คนไทยเข้าฟรี | X20: แหล่งท่องเที่ยว | AD20: ประมาณการ/แหล่งข้อมูลอื่น | AF20: ประมาณการจากค่าเข้า | AG20: 0 | AK20: เปิดแผนที่ ↗
A21: bangkok-attraction-yaowarat | B21: attraction | C21: เยาวราช | D21: เยาวราช | E21: 13.7397 | F21: 100.5099 | G21: localFood,nightlife | H21: 1 | I21: 4.7 | K21: 17:00-24:00 | L21: 17:00-24:00 | M21: 17:00-24:00 | N21: 17:00-24:00 | O21: 17:00-24:00 | P21: 17:00-24:00 | Q21: 120 | R21: 0 | S21: ไชน่าทาวน์ของกรุงเทพฯ ขึ้นชื่อสตรีทฟู้ดยามค่ำและร้านทองในตึกเก่า | V21: ตรวจเวลาเปิด | W21: เป็นถนน ใช้ช่วงสตรีทฟู้ดยามค่ำ (ประมาณการ) แผงลอยส่วนใหญ่หยุดวันจันทร์ ควรตรวจสอบ | X21: แหล่งท่องเที่ยว | AA21: ถ. เยาวราช | AC21: ถนนที่มีชื่อเสียง | AD21: ประมาณการ/แหล่งข้อมูลอื่น | AF21: ประมาณการจากค่าเข้า | AG21: 0 | AH21: ถ. เยาวราช กรุงเทพมหานคร | AJ21: ChIJ95Nh9yGZ4jARAjfcG2uIZFg | AK21: เปิดแผนที่ ↗
A22: bangkok-restaurant-mahanakhon-eatery | B22: restaurant | C22: Mahanakhon Eatery | D22: สีลม | E22: 13.723905 | F22: 100.52865 | G22: localFood,family | H22: 2 | I22: 4.6 | J22: 08:00-22:00 | K22: 08:00-22:00 | L22: 08:00-22:00 | M22: 08:00-22:00 | N22: 08:00-22:00 | O22: 08:00-22:00 | P22: 08:00-22:00 | Q22: 60 | R22: 0 | S22: ฟู้ดฮอลล์ใต้ตึกมหานคร รวมร้านอาหารไทยและนานาชาติ แวะก่อนขึ้น SkyWalk ได้ | U22: Y | X22: ร้านอาหาร | Y22: SkyWalk King Power Mahanakhon (คิงเพาเวอร์ มหานคร) | Z22: 0.02 | AA22: Mahanakhon Eatery | AB22: 495 | AC22: ศูนย์อาหาร | AD22: Google Maps (รายวัน) | AE22: ทุกวัน 08:00-22:00 | AF22: ประมาณการจากประเภทร้าน/ทำเล (ยังไม่ยืนยัน) | AH22: 96 ถ.นราธิวาสราชนครินทร์ สีลม บางรัก | AI22: +66 2 677 8721 | AJ22: ChIJpYfHXaef4jARpiefh3BHf1k | AK22: เปิดแผนที่ ↗
A23: bangkok-restaurant-babyccino-mahanakhon | B23: restaurant | C23: Babyccino Mahanakhon | D23: สีลม | E23: 13.72386 | F23: 100.52868 | G23: cafe,family | H23: 2 | I23: 4.7 | J23: 10:00-22:00 | K23: 10:00-22:00 | L23: 10:00-22:00 | M23: 10:00-22:00 | N23: 10:00-22:00 | O23: 10:00-22:00 | P23: 10:00-22:00 | Q23: 60 | R23: 0 | S23: คาเฟ่บรันช์ในมหานครคิวบ์ มีเมนูอาหารเช้า-กลางวันและเครื่องดื่ม | U23: Y | X23: ร้านอาหาร | Y23: SkyWalk King Power Mahanakhon (คิงเพาเวอร์ มหานคร) | Z23: 0.03 | AA23: Babyccino Mahanakhon | AB23: 489 | AC23: ภัตตาคารอาหารเช้าและกลางวัน | AD23: Google Maps (รายวัน) | AE23: ทุกวัน 10:00-22:00 | AF23: ประมาณการจากประเภทร้าน/ทำเล (ยังไม่ยืนยัน) | AH23: Mahanakhon Cube 96 ถ.นราธิวาสฯ สีลม บางรัก | AI23: +66 92 446 9222 | AJ23: ChIJL_Skva2Z4jARptt0z0enAIM | AK23: เปิดแผนที่ ↗
A24: bangkok-restaurant-the-standard-grill | B24: restaurant | C24: The Standard Grill | D24: สีลม | E24: 13.72353 | F24: 100.5283 | H24: 4 | I24: 4.8 | J24: 17:30-22:30 | K24: 17:30-22:30 | L24: 17:30-22:30 | M24: 17:30-22:30 | N24: 17:30-22:30 | O24: 12:00-22:30 | P24: 12:00-22:30 | Q24: 90 | R24: 0 | S24: ร้านสเต็กและอาหารอเมริกันในโรงแรม The Standard มหานคร | U24: Y | V24: ไม่มีแท็กที่ตรงประเภทอาหาร (อาหารต่างชาติ) | W24: เปิด 2 ช่วง (sun 12:00–15:00 / 17:30–22:30; sat 12:00–15:00 / 17:30–22:30) ระบบรองรับช่วงเดียว จึงใส่ช่วงรวม | X24: ร้านอาหาร | Y24: SkyWalk King Power Mahanakhon (คิงเพาเวอร์ มหานคร) | Z24: 0.06 | AA24: The Standard Grill | AB24: 1266 | AC24: ร้านอาหาร, ภัตตาคารอาหารอเมริกัน, ร้านสเต็ก | AD24: Google Maps (รายวัน) | AE24: จ-ศ 17:30-22:30 / ส-อา 12:00-15:00, 17:30-22:30 | AF24: ประมาณการจากประเภทร้าน/ทำเล (ยังไม่ยืนยัน) | AH24: ชั้น 5 The Standard Bangkok Mahanakhon 114 ถ.นราธิวาสฯ | AI24: +66 2 085 8888 | AJ24: ChIJtzsv7T2Z4jAR2fSNVxk9_Jc | AK24: เปิดแผนที่ ↗
A25: bangkok-restaurant-sugar-bliss-ashton-silom | B25: restaurant | C25: Sugar Bliss Coffee & Brunch (Ashton Silom) | D25: สีลม | E25: 13.726351 | F25: 100.52681 | G25: cafe | H25: 2 | I25: 5 | J25: 08:00-18:00 | K25: 08:00-18:00 | L25: 08:00-18:00 | M25: 08:00-18:00 | N25: 08:00-18:00 | O25: 08:00-18:00 | P25: 08:00-18:00 | Q25: 45 | R25: 0 | S25: คาเฟ่กาแฟและบรันช์ย่านสีลม ใกล้ตึกมหานคร | U25: Y | X25: ร้านเครื่องดื่ม | Y25: SkyWalk King Power Mahanakhon (คิงเพาเวอร์ มหานคร) | Z25: 0.32 | AA25: Sugar Bliss Coffee & Brunch (Ashton Silom) | AB25: 60 | AC25: ร้านกาแฟ | AD25: Google Maps (รายวัน) | AE25: ทุกวัน 08:00-18:00 | AF25: ประมาณการจากประเภทร้าน/ทำเล (ยังไม่ยืนยัน) | AH25: Ashton Silom ถ.สีลม สุริยวงศ์ บางรัก | AI25: +66 93 452 2989 | AJ25: ChIJ_9mRbwqZ4jAR5qjatMOK910 | AK25: เปิดแผนที่ ↗
A26: bangkok-restaurant-still-bean-silom | B26: restaurant | C26: Still Bean — Silom | D26: สีลม | E26: 13.727425 | F26: 100.53329 | G26: cafe | H26: 2 | I26: 4.9 | J26: 07:30-20:00 | K26: 07:30-20:00 | L26: 07:30-20:00 | M26: 07:30-20:00 | N26: 07:30-20:00 | O26: 07:30-20:00 | P26: 07:30-20:00 | Q26: 30 | R26: 0 | S26: ร้านกาแฟสเปเชียลตี้บนถนนคอนแวนต์ ย่านสีลม | U26: N | X26: ร้านเครื่องดื่ม | Y26: SkyWalk King Power Mahanakhon (คิงเพาเวอร์ มหานคร) | Z26: 0.64 | AA26: Still Bean — Silom | AB26: 602 | AC26: ร้านกาแฟ | AD26: Google Maps (รายวัน) | AE26: ทุกวัน 07:30-20:00 | AF26: ประมาณการจากประเภทร้าน/ทำเล (ยังไม่ยืนยัน) | AH26: 2, 3 ถ.คอนแวนต์ สีลม บางรัก | AI26: +66 2 000 0101 | AJ26: ChIJpY1mWCaf4jARIHPxN0HALGc | AK26: เปิดแผนที่ ↗
A27: bangkok-restaurant-gatta-cafe-park-silom | B27: restaurant | C27: GATTA Cafe (Park Silom) - Specialty Coffee | D27: สีลม | E27: 13.727861 | F27: 100.53353 | G27: cafe | H27: 2 | I27: 4.9 | J27: 07:00-17:30 | K27: 07:00-17:30 | L27: 07:00-17:30 | M27: 07:00-17:30 | N27: 07:00-17:30 | O27: 08:00-16:30 | P27: 08:00-16:30 | Q27: 30 | R27: 0 | S27: ร้านกาแฟสเปเชียลตี้และโรงคั่วกาแฟในพาร์คสีลม | U27: N | X27: ร้านเครื่องดื่ม | Y27: SkyWalk King Power Mahanakhon (คิงเพาเวอร์ มหานคร) | Z27: 0.69 | AA27: GATTA CAfe (Park Silom) - Specialty Coffee | AC27: ร้านกาแฟ, โรงคั่วกาแฟ, ร้านอุปกรณ์กาแฟ | AD27: ตารางของเพื่อน (Google ให้มาแค่ 1 วัน) | AE27: จ-ศ 07:00-17:30 / ส-อา 08:00-16:30 | AF27: ประมาณการจากประเภทร้าน/ทำเล (ยังไม่ยืนยัน) | AH27: ชั้น L Park Silom ถ.สีลม บางรัก | AI27: +66 96 079 8822 | AJ27: ChIJ54yK4R2f4jARqeeHInvT16Y | AK27: เปิดแผนที่ ↗
A28: bangkok-restaurant-brioche-from-heaven | B28: restaurant | C28: Brioche from Heaven | D28: สีลม | E28: 13.724035 | F28: 100.5296 | G28: cafe | H28: 2 | I28: 4.4 | J28: 08:30-18:30 | K28: 08:30-18:30 | L28: 08:30-18:30 | M28: 08:30-18:30 | N28: 08:30-18:30 | O28: 08:30-18:30 | P28: 08:30-18:30 | Q28: 30 | R28: 0 | S28: ร้านเบเกอรี่ขึ้นชื่อเรื่องบริยอช ย่านสีลม-นราธิวาสฯ | U28: N | X28: ร้านของหวาน | Y28: SkyWalk King Power Mahanakhon (คิงเพาเวอร์ มหานคร) | Z28: 0.12 | AA28: บริยอช ฟอร์ม เฮฟเว่น | AB28: 1411 | AC28: ร้านเบเกอรี่ | AD28: Google Maps (รายวัน) | AE28: ทุกวัน 08:30-18:30 | AF28: ประมาณการจากประเภทร้าน/ทำเล (ยังไม่ยืนยัน) | AH28: 156 ถ.นราธิวาสราชนครินทร์ สีลม บางรัก | AI28: +66 64 847 0049 | AJ28: ChIJsbfRmjGZ4jARcKFHjhSe1ls | AK28: เปิดแผนที่ ↗
A29: bangkok-restaurant-after-you-silom-complex | B29: restaurant | C29: After You Dessert Café (Silom Complex) | D29: สีลม | E29: 13.728473 | F29: 100.53504 | G29: cafe,family | H29: 2 | I29: 4.4 | J29: 10:30-21:00 | K29: 10:30-21:00 | L29: 10:30-21:00 | M29: 10:30-21:00 | N29: 10:30-21:00 | O29: 10:30-21:00 | P29: 10:30-21:00 | Q29: 45 | R29: 0 | S29: ร้านของหวานชื่อดัง ขึ้นชื่อเรื่องบิงซูและฮันนี่โทสต์ ในสีลมคอมเพล็กซ์ | U29: N | X29: ร้านของหวาน | Y29: SkyWalk King Power Mahanakhon (คิงเพาเวอร์ มหานคร) | Z29: 0.86 | AA29: อาฟเตอร์ ยู - สีลม คอมเพล็กซ์ | AB29: 1350 | AC29: ร้านขนมหวาน, ร้านเบเกอรี่ | AD29: Google Maps (รายวัน) | AE29: ทุกวัน 10:30-21:00 | AF29: ประมาณการจากประเภทร้าน/ทำเล (ยังไม่ยืนยัน) | AH29: Silom Complex ชั้น 2 191 ถ.สีลม บางรัก | AI29: +66 2 231 3255 | AJ29: ChIJa2em1dGY4jARkD433irtHU8 | AK29: เปิดแผนที่ ↗
A30: bangkok-restaurant-kyo-roll-en-silom-complex | B30: restaurant | C30: Kyo Roll En (Silom Complex) | D30: สีลม | E30: 13.728085 | F30: 100.53494 | G30: cafe | H30: 2 | I30: 4.1 | J30: 10:30-22:00 | K30: 10:30-22:00 | L30: 10:30-22:00 | M30: 10:30-22:00 | N30: 10:30-22:00 | O30: 10:30-22:00 | P30: 10:30-22:00 | Q30: 30 | R30: 0 | S30: ร้านโรลเค้กและของหวานสไตล์ญี่ปุ่น ในสีลมคอมเพล็กซ์ | U30: N | X30: ร้านของหวาน | Y30: SkyWalk King Power Mahanakhon (คิงเพาเวอร์ มหานคร) | Z30: 0.83 | AA30: เกียวโรลเอนสีลมคอมเพล็กซ์ | AB30: 61 | AC30: ร้านขนมหวาน | AD30: Google Maps (รายวัน) | AE30: ทุกวัน 10:30-22:00 | AF30: ประมาณการจากประเภทร้าน/ทำเล (ยังไม่ยืนยัน) | AH30: Silom Complex ชั้น B 191 ถ.สีลม บางรัก | AI30: +66 65 717 9010 | AJ30: ChIJr9hEAyyf4jARq1DOwvgEalo | AK30: เปิดแผนที่ ↗
A31: bangkok-restaurant-thong-heng-lee | B31: restaurant | C31: Thong Heng Lee Restaurant | D31: เกาะรัตนโกสินทร์ | E31: 13.752679 | F31: 100.48939 | G31: localFood | H31: 1 | I31: 4.8 | K31: 08:30-16:30 | L31: 08:30-16:30 | M31: 08:30-16:30 | N31: 08:30-16:30 | O31: 08:30-16:30 | P31: 08:30-16:30 | Q31: 60 | R31: 0 | S31: ร้านอาหารไทย-จีนย่านท่าช้าง ราคาย่อมเยา มีของหวานและไอศกรีม | U31: Y | X31: ร้านอาหาร | Y31: วัดพระศรีรัตนศาสดาราม (วัดพระแก้ว) | Z31: 0.38 | AA31: ร้านอาหารท่งเฮงหลี | AB31: 1591 | AC31: ภัตตาคารอาหารไทย, ร้านของหวาน, ร้านไอศกรีม | AD31: Google Maps (รายวัน) | AE31: อ-อา 08:30-16:30 (ปิดวันจันทร์) | AF31: ประมาณการจากประเภทร้าน/ทำเล (ยังไม่ยืนยัน) | AH31: 192-194 ถ.มหาราช พระบรมมหาราชวัง พระนคร | AI31: +66 81 649 4890 | AJ31: ChIJqda0RQmZ4jAR861kobU9SaE | AK31: เปิดแผนที่ ↗
A32: bangkok-restaurant-the-gate-grand-palace | B32: restaurant | C32: The Gate Grand Palace | D32: เกาะรัตนโกสินทร์ | E32: 13.752174 | F32: 100.48915 | G32: localFood | H32: 2 | I32: 4.5 | J32: 09:00-18:00 | K32: 09:00-18:00 | L32: 09:00-18:00 | M32: 09:00-18:00 | N32: 09:00-18:00 | O32: 09:00-18:00 | P32: 09:00-18:00 | Q32: 60 | R32: 0 | S32: ร้านอาหารไทยบนถนนหน้าพระลาน ตรงข้ามพระบรมมหาราชวัง | U32: Y | X32: ร้านอาหาร | Y32: วัดพระศรีรัตนศาสดาราม (วัดพระแก้ว) | Z32: 0.39 | AA32: เดอะ เกท (แกรนด์พาเลซ) | AB32: 621 | AC32: ภัตตาคารอาหารไทย | AD32: Google Maps (รายวัน) | AE32: ทุกวัน 09:00-18:00 | AF32: ประมาณการจากประเภทร้าน/ทำเล (ยังไม่ยืนยัน) | AH32: 77 ถ.หน้าพระลาน ท่าช้าง พระนคร | AI32: +66 82 752 4993 | AJ32: ChIJXSG1gOGZ4jARQWWzQjSY8Hw | AK32: เปิดแผนที่ ↗
A33: bangkok-restaurant-krua-na-wang | B33: restaurant | C33: Thai Royal Kitchen ครัวหน้าวัง | D33: เกาะรัตนโกสินทร์ | E33: 13.749529 | F33: 100.49827 | G33: localFood | H33: 2 | I33: 4.9 | J33: 05:30-14:00 | K33: 05:30-14:00 | L33: 05:30-14:00 | M33: 05:30-14:00 | N33: 05:30-14:00 | O33: 05:30-14:00 | P33: 05:30-14:00 | Q33: 60 | R33: 0 | S33: ร้านอาหารไทยใกล้วัดราชบพิธ เดินถึงพระบรมมหาราชวังได้ | U33: Y | X33: ร้านอาหาร | Y33: วัดพระศรีรัตนศาสดาราม (วัดพระแก้ว) | Z33: 0.64 | AA33: ครัวหน้าวัง | AB33: 427 | AC33: ภัตตาคารอาหารไทย | AD33: Google Maps (รายวัน) | AE33: ทุกวัน 05:30-14:00 (แนะนำสั่งล่วงหน้า) | AF33: ประมาณการจากประเภทร้าน/ทำเล (ยังไม่ยืนยัน) | AH33: 12 ถ.ราชบพิธ วัดราชบพิธ พระนคร | AI33: +66 63 965 5656 | AJ33: ChIJ3RQGqDKZ4jARor7IX-x0y0s | AK33: เปิดแผนที่ ↗
A34: bangkok-restaurant-tawang-thai-tea-wat-phra-kaew | B34: restaurant | C34: Tawang Thai Tea, Legendary of LIGOR @Wat Phra Kaew | D34: เกาะรัตนโกสินทร์ | E34: 13.75252 | F34: 100.49085 | G34: cafe,localFood | H34: 1 | I34: 4.9 | J34: 09:00-17:00 | K34: 09:00-17:00 | L34: 09:00-17:00 | M34: 09:00-17:00 | N34: 09:00-17:00 | O34: 09:00-17:00 | P34: 09:00-17:00 | Q34: 20 | R34: 0 | S34: ร้านชาไทยสูตรเมืองลิกอร์ (นครศรีธรรมราช) บนถนนหน้าพระลาน | U34: N | X34: ร้านเครื่องดื่ม | Y34: วัดพระศรีรัตนศาสดาราม (วัดพระแก้ว) | Z34: 0.23 | AA34: ท่าวัง ตำนานแห่งเมืองลิกอร์ สาขาวัดพระแก้ว | AB34: 103 | AC34: ร้านกาแฟ | AD34: Google Maps (รายวัน) | AE34: ทุกวัน 09:00-17:00 | AF34: ประมาณการจากประเภทร้าน/ทำเล (ยังไม่ยืนยัน) | AH34: 9 ถ.หน้าพระลาน พระบรมมหาราชวัง พระนคร | AI34: +66 88 980 9398 | AJ34: ChIJX1I3HwCZ4jARxCmOcCGCapw | AK34: เปิดแผนที่ ↗
A35: bangkok-restaurant-cloud-phranakhon | B35: restaurant | C35: Cloud Phranakhon | D35: เกาะรัตนโกสินทร์ | E35: 13.75562 | F35: 100.49205 | G35: cafe,localFood | H35: 2 | I35: 4.9 | J35: 07:00-21:00 | K35: 07:00-21:00 | L35: 07:00-21:00 | M35: 07:00-21:00 | N35: 07:00-21:00 | O35: 07:00-21:00 | P35: 07:00-21:00 | Q35: 60 | R35: 0 | S35: คาเฟ่และอาหารไทยมื้อเช้า-กลางวัน ในซอยหน้าพระธาตุ ใกล้ท่าช้าง | U35: Y | X35: ร้านเครื่องดื่ม | Y35: วัดพระศรีรัตนศาสดาราม (วัดพระแก้ว) | Z35: 0.46 | AA35: Cloud Phranakhon | AB35: 126 | AC35: ร้านกาแฟ, ภัตตาคารอาหารเช้า, ภัตตาคารอาหารเช้าและกลางวัน, ร้านอาหาร, ภัตตาคารอาหารไทย | AD35: Google Maps (รายวัน) | AE35: ทุกวัน 07:00-21:00 | AF35: ประมาณการจากประเภทร้าน/ทำเล (ยังไม่ยืนยัน) | AH35: ซ.หน้าพระธาตุ พระบรมมหาราชวัง พระนคร | AI35: +66 80 296 5549 | AJ35: ChIJ0VnuaBeZ4jARYxkgVt-fU-o | AK35: เปิดแผนที่ ↗
A36: bangkok-restaurant-chang-khua-tha-phra-chan | B36: restaurant | C36: ช่างคั่ว สาขาท่าพระจันทร์ | D36: เกาะรัตนโกสินทร์ | E36: 13.75591 | F36: 100.49041 | G36: cafe | H36: 2 | I36: 4.8 | J36: 08:00-16:00 | K36: 08:00-16:00 | L36: 08:00-16:00 | M36: 08:00-16:00 | N36: 08:00-16:00 | O36: 08:00-16:00 | P36: 08:00-16:00 | Q36: 30 | R36: 0 | S36: ร้านกาแฟคั่วเองย่านท่าพระจันทร์ ใกล้มหาวิทยาลัยธรรมศาสตร์ | U36: N | X36: ร้านเครื่องดื่ม | Y36: วัดพระศรีรัตนศาสดาราม (วัดพระแก้ว) | Z36: 0.55 | AA36: ช่างคั่ว สาขาท่าพระจันทร์ | AB36: 234 | AC36: ร้านกาแฟ | AD36: Google Maps (รายวัน) | AE36: ทุกวัน 08:00-16:00 | AF36: ประมาณการจากประเภทร้าน/ทำเล (ยังไม่ยืนยัน) | AH36: 5-7 ซ.ท่าพระจันทร์ พระบรมมหาราชวัง พระนคร | AI36: +66 96 395 9446 | AJ36: ChIJnx1_2XKZ4jARlAWQwKo5-_Y | AK36: เปิดแผนที่ ↗
A37: bangkok-restaurant-nuttaporn-ice-cream | B37: restaurant | C37: Nuttaporn Ice Cream (ไอศกรีมมะพร้าวนัฐพร) | D37: เกาะรัตนโกสินทร์ | E37: 13.75167 | F37: 100.4975 | G37: localFood | H37: 1 | I37: 4.5 | J37: 09:00-17:00 | K37: 09:00-17:00 | L37: 09:00-17:00 | M37: 09:00-17:00 | N37: 09:00-17:00 | O37: 09:00-17:00 | Q37: 20 | R37: 0 | S37: ไอศกรีมกะทิสดสูตรโบราณ ย่านแพร่งภูธร | U37: N | X37: ร้านของหวาน | Y37: วัดพระศรีรัตนศาสดาราม (วัดพระแก้ว) | Z37: 0.52 | AA37: นัฐพรไอศครีมกะทิสด | AC37: ร้านไอศกรีม | AD37: ตารางของเพื่อน (Google ให้มาแค่ 1 วัน) | AE37: จ-ส 09:00-17:00 (ปิดวันอาทิตย์) | AF37: ประมาณการจากประเภทร้าน/ทำเล (ยังไม่ยืนยัน) | AH37: 94 ถ.แพร่งภูธร ศาลเจ้าพ่อเสือ พระนคร | AI37: +66 89 826 5752 | AJ37: ChIJ5VJGvhGZ4jARSBZl5Kc7a2k | AK37: เปิดแผนที่ ↗
A38: bangkok-restaurant-lung-daeng-phraeng-nara | B38: restaurant | C38: ร้านลุงแดง (ขนมไทยโบราณ แพร่งนรา) | D38: เกาะรัตนโกสินทร์ | E38: 13.752426 | F38: 100.498 | G38: localFood | H38: 1 | I38: 4.7 | J38: 09:00-15:00 | K38: 09:00-15:00 | L38: 09:00-15:00 | M38: 09:00-15:00 | N38: 09:00-15:00 | Q38: 20 | R38: 0 | S38: ร้านขนมไทยโบราณย่านแพร่งนรา | U38: N | X38: ร้านของหวาน | Y38: วัดพระศรีรัตนศาสดาราม (วัดพระแก้ว) | Z38: 0.58 | AA38: ร้านลุงแดง | AB38: 63 | AC38: ร้านขนมหวาน | AD38: Google Maps (รายวัน) | AE38: จ-ศ 09:00-15:00 (ปิดเสาร์-อาทิตย์) | AF38: ประมาณการจากประเภทร้าน/ทำเล (ยังไม่ยืนยัน) | AH38: 112 ถ.แพร่งนรา ศาลเจ้าพ่อเสือ พระนคร | AI38: +66 2 622 0404 | AJ38: ChIJa0NEkBGZ4jARK8fGc1AlX4k | AK38: เปิดแผนที่ ↗
A39: bangkok-restaurant-paulette-bkk | B39: restaurant | C39: PAULETTE BKK | D39: เกาะรัตนโกสินทร์ | E39: 13.749523 | F39: 100.49804 | G39: cafe | H39: 2 | I39: 4.5 | J39: 07:30-18:30 | K39: 07:30-18:30 | L39: 07:30-18:30 | M39: 07:30-18:30 | N39: 07:30-18:30 | O39: 07:30-18:30 | P39: 07:30-18:30 | Q39: 45 | R39: 0 | S39: คาเฟ่และร้านขนมปังบนถนนเฟื่องนคร ใกล้วัดราชบพิธ | U39: N | X39: ร้านของหวาน | Y39: วัดพระศรีรัตนศาสดาราม (วัดพระแก้ว) | Z39: 0.62 | AA39: PAULETTE BKK | AB39: 662 | AC39: ร้านกาแฟ, ร้านขายขนมปัง | AD39: Google Maps (รายวัน) | AE39: ทุกวัน 07:30-18:30 | AF39: ประมาณการจากประเภทร้าน/ทำเล (ยังไม่ยืนยัน) | AH39: 65 ถ.เฟื่องนคร วัดราชบพิธ พระนคร | AI39: +66 63 674 6561 | AJ39: ChIJHdQm8CKZ4jARSeplrVUwAtg | AK39: เปิดแผนที่ ↗
A40: bangkok-restaurant-baan-tha-tien | B40: restaurant | C40: Baan ThaTien | D40: เกาะรัตนโกสินทร์ | E40: 13.744685 | F40: 100.49225 | G40: localFood,cafe | H40: 2 | I40: 4.5 | J40: 08:00-19:00 | K40: 08:00-19:00 | L40: 08:00-19:00 | M40: 08:00-19:00 | N40: 08:00-19:00 | O40: 08:00-19:00 | P40: 08:00-19:00 | Q40: 60 | R40: 0 | S40: ร้านอาหารไทยและคาเฟ่ย่านท่าเตียน ใกล้วัดโพธิ์ | U40: Y | X40: ร้านอาหาร | Y40: วัดพระเชตุพนวิมลมังคลาราม (วัดโพธิ์) | Z40: 0.2 | AA40: บ้านท่าเตียน | AB40: 1198 | AC40: ภัตตาคารอาหารไทย, ร้านกาแฟ | AD40: Google Maps (รายวัน) | AE40: ทุกวัน 08:00-19:00 | AF40: ประมาณการจากประเภทร้าน/ทำเล (ยังไม่ยืนยัน) | AH40: 392/2 ถ.มหาราช พระบรมมหาราชวัง พระนคร | AI40: +66 95 151 5545 | AJ40: ChIJAYJsTQSZ4jARi7QrBrmpxY4 | AK40: เปิดแผนที่ ↗
...

Sheet สรุป
A1: สรุปข้อมูลสถานที่กรุงเทพฯ
A2: ตัวเลขเป็นสูตรนับจากชีต places อัปเดตเองเมื่อแก้หรือเพิ่มแถว
A4: หมวด | B4: จำนวน | C4: เป้าหมาย #21
A5: attraction | B5: =COUNTIF(places!$B$3:$B$2000,"attraction") | C5: ≥ 25
A6: restaurant | B6: =COUNTIF(places!$B$3:$B$2000,"restaurant") | C6: ≥ 20
A7: └ ใช้เป็นมื้อหลักได้ (Y) | B7: =COUNTIFS(places!$B$3:$B$2000,"restaurant",places!$U$3:$U$2000,"Y")
A8: accommodation | B8: =COUNTIF(places!$B$3:$B$2000,"accommodation") | C8: ≥ 8
A9: แถวที่ต้องตรวจ (สีเหลือง) | B9: =COUNTIF(places!$V$3:$V$2000,"?*") | C9: 0
A11: ระดับราคา (restaurant) | B11: จำนวน | C11: ความหมาย (ต่อคนต่อมื้อ)
A12: 1 ฿ | B12: =COUNTIFS(places!$B$3:$B$2000,"restaurant",places!$H$3:$H$2000,1) | C12: ไม่เกิน ~150 บาท
A13: 2 ฿฿ | B13: =COUNTIFS(places!$B$3:$B$2000,"restaurant",places!$H$3:$H$2000,2) | C13: ~150–400 บาท
A14: 3 ฿฿฿ | B14: =COUNTIFS(places!$B$3:$B$2000,"restaurant",places!$H$3:$H$2000,3) | C14: ~400–1,000 บาท
A15: 4 ฿฿฿฿ | B15: =COUNTIFS(places!$B$3:$B$2000,"restaurant",places!$H$3:$H$2000,4) | C15: มากกว่า ~1,000 บาท
A17: ย่าน | B17: จำนวนทั้งหมด
A18: ริมแม่น้ำเจ้าพระยา | B18: =COUNTIF(places!$D$3:$D$2000,"ริมแม่น้ำเจ้าพระยา")
A19: สยาม/ปทุมวัน | B19: =COUNTIF(places!$D$3:$D$2000,"สยาม/ปทุมวัน")
A20: เกาะรัตนโกสินทร์ | B20: =COUNTIF(places!$D$3:$D$2000,"เกาะรัตนโกสินทร์")
A21: จตุจักร | B21: =COUNTIF(places!$D$3:$D$2000,"จตุจักร")
A22: สุขุมวิท | B22: =COUNTIF(places!$D$3:$D$2000,"สุขุมวิท")
A23: คลองบางหลวง | B23: =COUNTIF(places!$D$3:$D$2000,"คลองบางหลวง")
A24: บรรทัดทอง | B24: =COUNTIF(places!$D$3:$D$2000,"บรรทัดทอง")
A25: ปากคลองตลาด | B25: =COUNTIF(places!$D$3:$D$2000,"ปากคลองตลาด")
A26: บางลำพู | B26: =COUNTIF(places!$D$3:$D$2000,"บางลำพู")
A27: เยาวราช | B27: =COUNTIF(places!$D$3:$D$2000,"เยาวราช")
A28: เอกมัย | B28: =COUNTIF(places!$D$3:$D$2000,"เอกมัย")
A29: คันนายาว | B29: =COUNTIF(places!$D$3:$D$2000,"คันนายาว")
A30: ตลาดพลู-ภาษีเจริญ | B30: =COUNTIF(places!$D$3:$D$2000,"ตลาดพลู-ภาษีเจริญ")
A31: สีลม | B31: =COUNTIF(places!$D$3:$D$2000,"สีลม")

Sheet ต้นฉบับ_ร้าน
A1: ลำดับ | B1: แหล่งท่องเที่ยว | C1: ประเภท | D1: ชื่อร้าน | E1: ละติจูด | F1: ลองจิจูด | G1: ระยะห่างจากแหล่งท่องเที่ยว (กม.) | H1: ที่อยู่ | I1: วัน-เวลาเปิดให้บริการ | J1: เบอร์โทร | K1: ลิงก์ Google Maps | L1: สถานะ (ตรวจสอบ 3 ต.ค. 2569)
A2: 1 | B2: SkyWalk King Power Mahanakhon (คิงเพาเวอร์ มหานคร) | C2: ร้านอาหาร | D2: Mahanakhon Eatery | E2: 13.723905 | F2: 100.52865 | G2: 0.02 | H2: 96 ถ.นราธิวาสราชนครินทร์ สีลม บางรัก | I2: ทุกวัน 08:00-22:00 | J2: +66 2 677 8721 | K2: https://www.google.com/maps/search/?api=1&query_place_id=ChIJpYfHXaef4jARpiefh3BHf1k | L2: เปิดให้บริการ (มีเวลาทำการใน Google Maps)
A3: 2 | B3: SkyWalk King Power Mahanakhon (คิงเพาเวอร์ มหานคร) | C3: ร้านอาหาร | D3: Babyccino Mahanakhon | E3: 13.72386 | F3: 100.52868 | G3: 0.03 | H3: Mahanakhon Cube 96 ถ.นราธิวาสฯ สีลม บางรัก | I3: ทุกวัน 10:00-22:00 | J3: +66 92 446 9222 | K3: https://www.google.com/maps/search/?api=1&query_place_id=ChIJL_Skva2Z4jARptt0z0enAIM | L3: เปิดให้บริการ (มีเวลาทำการใน Google Maps)
A4: 3 | B4: SkyWalk King Power Mahanakhon (คิงเพาเวอร์ มหานคร) | C4: ร้านอาหาร | D4: The Standard Grill | E4: 13.72353 | F4: 100.5283 | G4: 0.06 | H4: ชั้น 5 The Standard Bangkok Mahanakhon 114 ถ.นราธิวาสฯ | I4: จ-ศ 17:30-22:30 / ส-อา 12:00-15:00, 17:30-22:30 | J4: +66 2 085 8888 | K4: https://www.google.com/maps/search/?api=1&query_place_id=ChIJtzsv7T2Z4jAR2fSNVxk9_Jc | L4: เปิดให้บริการ (มีเวลาทำการใน Google Maps)
A5: 4 | B5: SkyWalk King Power Mahanakhon (คิงเพาเวอร์ มหานคร) | C5: ร้านเครื่องดื่ม | D5: Sugar Bliss Coffee & Brunch (Ashton Silom) | E5: 13.726351 | F5: 100.52681 | G5: 0.32 | H5: Ashton Silom ถ.สีลม สุริยวงศ์ บางรัก | I5: ทุกวัน 08:00-18:00 | J5: +66 93 452 2989 | K5: https://www.google.com/maps/search/?api=1&query_place_id=ChIJ_9mRbwqZ4jAR5qjatMOK910 | L5: เปิดให้บริการ (มีเวลาทำการใน Google Maps)
A6: 5 | B6: SkyWalk King Power Mahanakhon (คิงเพาเวอร์ มหานคร) | C6: ร้านเครื่องดื่ม | D6: Still Bean — Silom | E6: 13.727425 | F6: 100.53329 | G6: 0.64 | H6: 2, 3 ถ.คอนแวนต์ สีลม บางรัก | I6: ทุกวัน 07:30-20:00 | J6: +66 2 000 0101 | K6: https://www.google.com/maps/search/?api=1&query_place_id=ChIJpY1mWCaf4jARIHPxN0HALGc | L6: เปิดให้บริการ (มีเวลาทำการใน Google Maps)
A7: 6 | B7: SkyWalk King Power Mahanakhon (คิงเพาเวอร์ มหานคร) | C7: ร้านเครื่องดื่ม | D7: GATTA Cafe (Park Silom) - Specialty Coffee | E7: 13.727861 | F7: 100.53353 | G7: 0.69 | H7: ชั้น L Park Silom ถ.สีลม บางรัก | I7: จ-ศ 07:00-17:30 / ส-อา 08:00-16:30 | J7: +66 96 079 8822 | K7: https://www.google.com/maps/search/?api=1&query_place_id=ChIJ54yK4R2f4jARqeeHInvT16Y | L7: เปิดให้บริการ (มีเวลาทำการใน Google Maps)
A8: 7 | B8: SkyWalk King Power Mahanakhon (คิงเพาเวอร์ มหานคร) | C8: ร้านของหวาน | D8: Brioche from Heaven | E8: 13.724035 | F8: 100.5296 | G8: 0.12 | H8: 156 ถ.นราธิวาสราชนครินทร์ สีลม บางรัก | I8: ทุกวัน 08:30-18:30 | J8: +66 64 847 0049 | K8: https://www.google.com/maps/search/?api=1&query_place_id=ChIJsbfRmjGZ4jARcKFHjhSe1ls | L8: เปิดให้บริการ (มีเวลาทำการใน Google Maps)
A9: 8 | B9: SkyWalk King Power Mahanakhon (คิงเพาเวอร์ มหานคร) | C9: ร้านของหวาน | D9: After You Dessert Café (Silom Complex) | E9: 13.728473 | F9: 100.53504 | G9: 0.86 | H9: Silom Complex ชั้น 2 191 ถ.สีลม บางรัก | I9: ทุกวัน 10:30-21:00 | J9: +66 2 231 3255 | K9: https://www.google.com/maps/search/?api=1&query_place_id=ChIJa2em1dGY4jARkD433irtHU8 | L9: เปิดให้บริการ (มีเวลาทำการใน Google Maps)
A10: 9 | B10: SkyWalk King Power Mahanakhon (คิงเพาเวอร์ มหานคร) | C10: ร้านของหวาน | D10: Kyo Roll En (Silom Complex) | E10: 13.728085 | F10: 100.53494 | G10: 0.83 | H10: Silom Complex ชั้น B 191 ถ.สีลม บางรัก | I10: ทุกวัน 10:30-22:00 | J10: +66 65 717 9010 | K10: https://www.google.com/maps/search/?api=1&query_place_id=ChIJr9hEAyyf4jARq1DOwvgEalo | L10: เปิดให้บริการ (มีเวลาทำการใน Google Maps)
A11: 10 | B11: วัดพระศรีรัตนศาสดาราม (วัดพระแก้ว) | C11: ร้านอาหาร | D11: Thong Heng Lee Restaurant | E11: 13.752679 | F11: 100.48939 | G11: 0.38 | H11: 192-194 ถ.มหาราช พระบรมมหาราชวัง พระนคร | I11: อ-อา 08:30-16:30 (ปิดวันจันทร์) | J11: +66 81 649 4890 | K11: https://www.google.com/maps/search/?api=1&query_place_id=ChIJqda0RQmZ4jAR861kobU9SaE | L11: เปิดให้บริการ (มีเวลาทำการใน Google Maps)
A12: 11 | B12: วัดพระศรีรัตนศาสดาราม (วัดพระแก้ว) | C12: ร้านอาหาร | D12: The Gate Grand Palace | E12: 13.752174 | F12: 100.48915 | G12: 0.39 | H12: 77 ถ.หน้าพระลาน ท่าช้าง พระนคร | I12: ทุกวัน 09:00-18:00 | J12: +66 82 752 4993 | K12: https://www.google.com/maps/search/?api=1&query_place_id=ChIJXSG1gOGZ4jARQWWzQjSY8Hw | L12: เปิดให้บริการ (มีเวลาทำการใน Google Maps)
A13: 12 | B13: วัดพระศรีรัตนศาสดาราม (วัดพระแก้ว) | C13: ร้านอาหาร | D13: Thai Royal Kitchen ครัวหน้าวัง | E13: 13.749529 | F13: 100.49827 | G13: 0.64 | H13: 12 ถ.ราชบพิธ วัดราชบพิธ พระนคร | I13: ทุกวัน 05:30-14:00 (แนะนำสั่งล่วงหน้า) | J13: +66 63 965 5656 | K13: https://www.google.com/maps/search/?api=1&query_place_id=ChIJ3RQGqDKZ4jARor7IX-x0y0s | L13: เปิดให้บริการ (มีเวลาทำการใน Google Maps)
... A172: 171 | B172: สะพานพระพุทธยอดฟ้า (สะพานพุทธ) | C172: ร้านของหวาน | D172: Mi Thai Dessert | E172: 13.739214 | F172: 100.5067 | G172: 0.98 | H172: 538 ตรอกโรงโคม สัมพันธวงศ์ (ติดโรงเรียนเผยอิง) | I172: ทุกวัน 10:00-19:00 | J172: +66 95 818 2919 | K172: https://www.google.com/maps/search/?api=1&query_place_id=ChIJg4vvVgCZ4jARZMzIP6_hBP0 | L172: เปิดให้บริการ (มีเวลาทำการใน Google Maps)

Sheet ต้นฉบับ_แหล่งท่องเที่ยว
A1: ลำดับ | B1: แหล่งท่องเที่ยว | C1: ละติจูด | D1: ลองจิจูด | E1: ร้านอาหาร | F1: ร้านเครื่องดื่ม | G1: ร้านของหวาน | H1: รวม
A2: 1 | B2: SkyWalk King Power Mahanakhon (คิงเพาเวอร์ มหานคร) | C2: 13.72401 | D2: 100.52848 | E2: =COUNTIFS('ต้นฉบับ_ร้าน'!$B:$B,$B2,'ต้นฉบับ_ร้าน'!$C:$C,E$1) | F2: =COUNTIFS('ต้นฉบับ_ร้าน'!$B:$B,$B2,'ต้นฉบับ_ร้าน'!$C:$C,F$1) | G2: =COUNTIFS('ต้นฉบับ_ร้าน'!$B:$B,$B2,'ต้นฉบับ_ร้าน'!$C:$C,G$1) | H2: =SUM(E2:G2)
A3: 2 | B3: วัดพระศรีรัตนศาสดาราม (วัดพระแก้ว) | C3: 13.7515 | D3: 100.4927 | E3: =COUNTIFS('ต้นฉบับ_ร้าน'!$B:$B,$B3,'ต้นฉบับ_ร้าน'!$C:$C,E$1) | F3: =COUNTIFS('ต้นฉบับ_ร้าน'!$B:$B,$B3,'ต้นฉบับ_ร้าน'!$C:$C,F$1) | G3: =COUNTIFS('ต้นฉบับ_ร้าน'!$B:$B,$B3,'ต้นฉบับ_ร้าน'!$C:$C,G$1) | H3: =SUM(E3:G3)
A4: 3 | B4: วัดพระเชตุพนวิมลมังคลาราม (วัดโพธิ์) | C4: 13.74642 | D4: 100.49277 | E4: =COUNTIFS('ต้นฉบับ_ร้าน'!$B:$B,$B4,'ต้นฉบับ_ร้าน'!$C:$C,E$1) | F4: =COUNTIFS('ต้นฉบับ_ร้าน'!$B:$B,$B4,'ต้นฉบับ_ร้าน'!$C:$C,F$1) | G4: =COUNTIFS('ต้นฉบับ_ร้าน'!$B:$B,$B4,'ต้นฉบับ_ร้าน'!$C:$C,G$1) | H4: =SUM(E4:G4)
A5: 4 | B5: วัดอรุณราชวรารามราชวรมหาวิหาร | C5: 13.74387 | D5: 100.48844 | E5: =COUNTIFS('ต้นฉบับ_ร้าน'!$B:$B,$B5,'ต้นฉบับ_ร้าน'!$C:$C,E$1) | F5: =COUNTIFS('ต้นฉบับ_ร้าน'!$B:$B,$B5,'ต้นฉบับ_ร้าน'!$C:$C,F$1) | G5: =COUNTIFS('ต้นฉบับ_ร้าน'!$B:$B,$B5,'ต้นฉบับ_ร้าน'!$C:$C,G$1) | H5: =SUM(E5:G5)
A6: 5 | B6: วัดปากน้ำภาษีเจริญ | C6: 13.72178 | D6: 100.47036 | E6: =COUNTIFS('ต้นฉบับ_ร้าน'!$B:$B,$B6,'ต้นฉบับ_ร้าน'!$C:$C,E$1) | F6: =COUNTIFS('ต้นฉบับ_ร้าน'!$B:$B,$B6,'ต้นฉบับ_ร้าน'!$C:$C,F$1) | G6: =COUNTIFS('ต้นฉบับ_ร้าน'!$B:$B,$B6,'ต้นฉบับ_ร้าน'!$C:$C,G$1) | H6: =SUM(E6:G6)
A7: 6 | B7: บรรทัดทอง (ถ.บรรทัดทอง) | C7: 13.7392 | D7: 100.5243 | E7: =COUNTIFS('ต้นฉบับ_ร้าน'!$B:$B,$B7,'ต้นฉบับ_ร้าน'!$C:$C,E$1) | F7: =COUNTIFS('ต้นฉบับ_ร้าน'!$B:$B,$B7,'ต้นฉบับ_ร้าน'!$C:$C,F$1) | G7: =COUNTIFS('ต้นฉบับ_ร้าน'!$B:$B,$B7,'ต้นฉบับ_ร้าน'!$C:$C,G$1) | H7: =SUM(E7:G7)
A8: 7 | B8: เยาวราช | C8: 13.7397 | D8: 100.5099 | E8: =COUNTIFS('ต้นฉบับ_ร้าน'!$B:$B,$B8,'ต้นฉบับ_ร้าน'!$C:$C,E$1) | F8: =COUNTIFS('ต้นฉบับ_ร้าน'!$B:$B,$B8,'ต้นฉบับ_ร้าน'!$C:$C,F$1) | G8: =COUNTIFS('ต้นฉบับ_ร้าน'!$B:$B,$B8,'ต้นฉบับ_ร้าน'!$C:$C,G$1) | H8: =SUM(E8:G8)
A9: 8 | B9: คลองบางหลวง (Artist House / ตลาดน้ำคลองบางหลวง ภาษีเจริญ) | C9: 13.7312 | D9: 100.4633 | E9: =COUNTIFS('ต้นฉบับ_ร้าน'!$B:$B,$B9,'ต้นฉบับ_ร้าน'!$C:$C,E$1) | F9: =COUNTIFS('ต้นฉบับ_ร้าน'!$B:$B,$B9,'ต้นฉบับ_ร้าน'!$C:$C,F$1) | G9: =COUNTIFS('ต้นฉบับ_ร้าน'!$B:$B,$B9,'ต้นฉบับ_ร้าน'!$C:$C,G$1) | H9: =SUM(E9:G9)
A10: 9 | B10: ย่านพระอาทิตย์ (ถ.พระอาทิตย์ บางลำพู) | C10: 13.7632 | D10: 100.4945 | E10: =COUNTIFS('ต้นฉบับ_ร้าน'!$B:$B,$B10,'ต้นฉบับ_ร้าน'!$C:$C,E$1) | F10: =COUNTIFS('ต้นฉบับ_ร้าน'!$B:$B,$B10,'ต้นฉบับ_ร้าน'!$C:$C,F$1) | G10: =COUNTIFS('ต้นฉบับ_ร้าน'!$B:$B,$B10,'ต้นฉบับ_ร้าน'!$C:$C,G$1) | H10: =SUM(E10:G10)
A11: 10 | B11: หอศิลปวัฒนธรรมแห่งกรุงเทพมหานคร (BACC) | C11: 13.74673 | D11: 100.53022 | E11: =COUNTIFS('ต้นฉบับ_ร้าน'!$B:$B,$B11,'ต้นฉบับ_ร้าน'!$C:$C,E$1) | F11: =COUNTIFS('ต้นฉบับ_ร้าน'!$B:$B,$B11,'ต้นฉบับ_ร้าน'!$C:$C,F$1) | G11: =COUNTIFS('ต้นฉบับ_ร้าน'!$B:$B,$B11,'ต้นฉบับ_ร้าน'!$C:$C,G$1) | H11: =SUM(E11:G11)
A12: 11 | B12: Asiatique The Riverfront | C12: 13.70442 | D12: 100.50327 | E12: =COUNTIFS('ต้นฉบับ_ร้าน'!$B:$B,$B12,'ต้นฉบับ_ร้าน'!$C:$C,E$1) | F12: =COUNTIFS('ต้นฉบับ_ร้าน'!$B:$B,$B12,'ต้นฉบับ_ร้าน'!$C:$C,F$1) | G12: =COUNTIFS('ต้นฉบับ_ร้าน'!$B:$B,$B12,'ต้นฉบับ_ร้าน'!$C:$C,G$1) | H12: =SUM(E12:G12)
A13: 12 | B13: ท้องฟ้าจำลองกรุงเทพ (เอกมัย) | C13: 13.71954 | D13: 100.58278 | E13: =COUNTIFS('ต้นฉบับ_ร้าน'!$B:$B,$B13,'ต้นฉบับ_ร้าน'!$C:$C,E$1) | F13: =COUNTIFS('ต้นฉบับ_ร้าน'!$B:$B,$B13,'ต้นฉบับ_ร้าน'!$C:$C,F$1) | G13: =COUNTIFS('ต้นฉบับ_ร้าน'!$B:$B,$B13,'ต้นฉบับ_ร้าน'!$C:$C,G$1) | H13: =SUM(E13:G13)
... A20: 19 | B20: สะพานพระพุทธยอดฟ้า (สะพานพุทธ) | C20: 13.73928 | D20: 100.4976 | E20: =COUNTIFS('ต้นฉบับ_ร้าน'!$B:$B,$B20,'ต้นฉบับ_ร้าน'!$C:$C,E$1) | F20: =COUNTIFS('ต้นฉบับ_ร้าน'!$B:$B,$B20,'ต้นฉบับ_ร้าน'!$C:$C,F$1) | G20: =COUNTIFS('ต้นฉบับ_ร้าน'!$B:$B,$B20,'ต้นฉบับ_ร้าน'!$C:$C,G$1) | H20: =SUM(E20:G20)
B21: รวมทั้งหมด | E21: =SUM(E2:E20) | F21: =SUM(F2:F20) | G21: =SUM(G2:G20) | H21: =SUM(H2:H20)

Sheet ต้นฉบับ_หมายเหตุ
A1: หัวข้อ | B1: รายละเอียด
A2: ที่มาข้อมูล | B2: ข้อมูลร้านค้า พิกัด เวลาทำการ เบอร์โทร และรหัสสถานที่ (place_id) ดึงจาก Google Places (Google Maps) เมื่อวันที่ 3 ต.ค. 2569
A3: นิยามคำว่า "เปิดให้บริการ" | B3: ร้านมีสถานะประกอบกิจการอยู่ใน Google Maps (ไม่ใช่ปิดถาวร/ปิดชั่วคราว) และมีวัน-เวลาทำการระบุไว้ ไม่ได้โทรยืนยันกับร้านรายร้าน แนะนำให้เช็กเวลาล่าสุดจากลิงก์ก่อนเดินทาง
A4: ร้านที่เปิดเฉพาะบางวัน | B4: ดูคอลัมน์ "วัน-เวลาเปิดให้บริการ" เช่น ร้านปิดวันจันทร์/อังคาร/พุธ/อาทิตย์ ร้านในตลาดจตุจักรบางร้านเปิดเฉพาะเสาร์-อาทิตย์ และบางร้านเปิดเฉพาะช่วงเย็น
A5: พิกัด | B5: ละติจูด/ลองจิจูดของแต่ละร้านมาจาก Google Maps (WGS84) ส่วนพิกัดแหล่งท่องเที่ยวอยู่ในชีต "แหล่งท่องเที่ยว"
A6: ระยะห่าง | B6: คำนวณเป็นระยะทางเส้นตรง (Haversine) จากจุดอ้างอิงแหล่งท่องเที่ยวถึงร้าน ไม่ใช่ระยะเดินจริง
A7: ลิงก์ | B7: ลิงก์ Google Maps สร้างจากรหัสสถานที่ของแต่ละร้าน คลิกแล้วเปิดตำแหน่งร้านนั้นโดยตรง
A8: คลองบางหลวง | B8: ตีความเป็นย่านคลองบางหลวง-บ้านศิลปิน/ตลาดน้ำคลองบางหลวง (ซ.เพชรเกษม 20 เขตภาษีเจริญ) หากหมายถึงจุดอื่นของคลองบางหลวง (เช่น ฝั่งบางกอกน้อย) แจ้งได้เพื่อค้นหาใหม่
A9: สวนสยาม | B9: Google Maps แสดงชื่อ Siam Amazing Park (เขตคันนายาว) ใช้พิกัดนั้นเป็นจุดอ้างอิง
A10: เยาวราช | B10: ผู้ใช้ระบุซ้ำ 2 ครั้งในรายการ นับเป็นแหล่งเดียว รวมแหล่งท่องเที่ยวทั้งหมด 19 แห่ง
A11: ห้างสรรพสินค้า | B11: ร้านใน Siam Paragon / ICONSIAM อยู่ภายในห้างหรือบริเวณรอบห้าง ระยะเส้นตรงบางร้านอยู่ห่าง 0.5-1.5 กม.
